Workbook
Name AntennaGrowth: Assumptions!$B$24
Name BldgSF: Assumptions!$B$5
Name CatchupGP: Assumptions!$B$71
Name CloseDate: Assumptions!$B$12
Name DispCost: Assumptions!$B$17
Name ExitCap: Assumptions!$B$16
Name ExpGrowth: Assumptions!$B$21
Name GPShare: Assumptions!$B$67
Name GPTarget: Assumptions!$B$72
Name HoldMonths: Assumptions!$B$15
Name LeaseTable: Assumptions!$A$56:$J$59
Name LPShare: Assumptions!$B$68
Name MgmtFeePct: Assumptions!$B$41
Name ParkGrowth: Assumptions!$B$23
Name PrefMo: Assumptions!$B$70
Name PurchasePrice: Assumptions!$B$6
Name ReimbPool: Assumptions!$B$40
Name RenewDiscount: Assumptions!$B$62
Name RenoBudget: Assumptions!$B$50
Name RenoDuration: Assumptions!$B$51
Name RentGrowth: Assumptions!$B$20
Name ReservesGrowth: Assumptions!$B$25
Name ReservesPSF: Assumptions!$B$42
Name ResidGP: Assumptions!$B$73
Name ResidLP: Assumptions!$B$74
Name SpecBuildout: Assumptions!$B$64
Name SpecTI: Assumptions!$B$63

Sheet Assumptions
A1: SouthPark Centre
A2: 4800 Sharon Road, Charlotte, NC 2821 | B2: Class B+ Multi-Tenant Office | D2: All inputs blue, formulas black
A4: PROPERTY
A5: Building SF (RSF) | B5: 280000 | C5: Total rentable area
A6: Purchase Price | B6: 50000000 | C6: VP revised down from Broker Guidance of $52.0m
A7: Acquisition Costs (% of gross) | B7: 0.03
A8: Price per SF | B8: =B6/B5 -> 178.57143 | C8: = Price / SF
A9: Stories | B9: 8
A10: Floor Plate (SF) | B10: 35000
A11: Parking Spaces | B11: 1176 | C11: 4.2 per 1,000 SF
A12: Close Date | B12: 46265 | C12: Projection month 0 = this month
A14: HOLD & EXIT
A15: Hold Period (months) | B15: 60 | C15: 5 years
A16: Exit Cap Rate | B16: 0.0775
A17: Disposition Costs (% of gross) | B17: 0.02
A19: GROWTH & ESCALATION
A20: Rent Growth (annual) | B20: 0.027 | C20: 30-yr US CPI avg per Standard Guide
A21: Expense Growth (annual) | B21: 0.027
A22: Stabilised Occupancy | B22: 0.88
A23: Parking Income Growth | B23: 0.025
A24: Antenna Income Growth | B24: 0.02
A25: Building Reserves Growth | B25: 0.025
A27: OPERATING EXPENSES (Annual, Year 1) | C27: Reimbursable?
A28: Real Estate Taxes | B28: 742000 | C28: Yes
A29: Insurance | B29: 210000 | C29: Yes
A30: Utilities | B30: 700000 | C30: Yes
A31: Repairs & Maintenance | B31: 490000 | C31: Yes
A32: Janitorial | B32: 378000 | C32: Yes
A33: Landscaping | B33: 84000 | C33: Yes
A34: Security | B34: 112000 | C34: Yes
A35: Elevator | B35: 50400 | C35: Yes
A36: HVAC | B36: 98000 | C36: Yes
A37: General & Admin | B37: 67200 | C37: Yes
A38: Marketing | B38: 39200 | C38: No
A39: Total OpEx (ex-mgmt fee) | B39: =SUM(B28:B38) -> 2970800
A40: Reimbursable OpEx Pool | B40: =SUMIF(C28:C38,"Yes",B28:B38) -> 2931600 | C40: Excl. marketing & mgmt fee
A41: Management Fee (% of EGI) | B41: 0.035
A42: Building Reserves ($/SF/yr) | B42: 0.5
A44: OTHER INCOME (Annual) | C44: Growth
A45: Parking Income | B45: 230000 | C45: =B23 -> 0.025
...

Sheet Rent Roll
B1: SouthPark Centre — Rent Roll
O3: Cols N–U: occupied = expiry mo# + size lookups; vacant = lease-up commencement mo# (blue) + size lookups
A4: Size Rank | B4: # | C4: Tenant | D4: Suite | E4: Flr | F4: SF | G4: Rent $/SF | H4: Annual Rent | I4: Esc % | J4: Esc Mo | K4: Start | L4: Expiry | M4: Renewal | N4: Status | O4: Expiry Mo# | P4: Size Key | Q4: Bucket | R4: Mkt Rent $/SF | S4: Downtime | T4: New TI $/SF | U4: LC % | V4: Free New | W4: Renew % | X4: Blend Rent $/SF | Y4: 1st Esc Date >close
A5: =RANK(F5,$F$5:$F$32) -> 1 | B5: 1 | C5: Meridian Financial Group | D5: 600-820 | E5: 6-8 | F5: 76000 | G5: 19.5 | H5: =F5*G5 -> 1482000 | I5: 0.025 | J5: 11 | K5: 42675 | L5: 46326 | M5: None | N5: Departing | O5: =DATEDIF(CloseDate,L5,"m")+1 -> 3 | P5: =LOOKUP(F5,{0,2000,5000,15000}) -> 15000 | Q5: =VLOOKUP(P5,LeaseTable,2,FALSE) -> >15,000 | R5: =VLOOKUP(P5,LeaseTable,3,FALSE) -> 25 | S5: =VLOOKUP(P5,LeaseTable,5,FALSE) -> 4 | T5: =VLOOKUP(P5,LeaseTable,6,FALSE) -> 40 | U5: =VLOOKUP(P5,LeaseTable,8,FALSE) -> 0.04 | V5: =VLOOKUP(P5,LeaseTable,9,FALSE) -> 2 | W5: 0 | X5: =R5*(W5*RenewDiscount+(1-W5)) -> 25 | Y5: =IF(J5="","",EOMONTH(DATE(YEAR(CloseDate)+IF(J5>MONTH(CloseDate),0,1),J5,1),0)) -> 46356
A6: =RANK(F6,$F$5:$F$32) -> 2 | B6: 2 | C6: Southeast Regional Health | D6: 200 | E6: 2 | F6: 24000 | G6: 21.5 | H6: =F6*G6 -> 516000 | I6: 0.03 | J6: 4 | K6: 43556 | L6: 47208 | M6: 1x5yr | N6: Occupied | O6: =DATEDIF(CloseDate,L6,"m")+1 -> 32 | P6: =LOOKUP(F6,{0,2000,5000,15000}) -> 15000 | Q6: =VLOOKUP(P6,LeaseTable,2,FALSE) -> >15,000 | R6: =VLOOKUP(P6,LeaseTable,3,FALSE) -> 25 | S6: =VLOOKUP(P6,LeaseTable,5,FALSE) -> 4 | T6: =VLOOKUP(P6,LeaseTable,6,FALSE) -> 40 | U6: =VLOOKUP(P6,LeaseTable,8,FALSE) -> 0.04 | V6: =VLOOKUP(P6,LeaseTable,9,FALSE) -> 2 | W6: =VLOOKUP(P6,LeaseTable,4,FALSE) -> 0.75 | X6: =R6*(W6*RenewDiscount+(1-W6)) -> 24.0625 | Y6: =IF(J6="","",EOMONTH(DATE(YEAR(CloseDate)+IF(J6>MONTH(CloseDate),0,1),J6,1),0)) -> 46507
A7: =RANK(F7,$F$5:$F$32) -> 3 | B7: 3 | C7: Carter & Associates Law | D7: 310 | E7: 3 | F7: 12000 | G7: 22 | H7: =F7*G7 -> 264000 | I7: 0.025 | J7: 10 | K7: 44835 | L7: 46660 | M7: None | N7: Occupied | O7: =DATEDIF(CloseDate,L7,"m")+1 -> 13 | P7: =LOOKUP(F7,{0,2000,5000,15000}) -> 5000 | Q7: =VLOOKUP(P7,LeaseTable,2,FALSE) -> 5,000-15,000 | R7: =VLOOKUP(P7,LeaseTable,3,FALSE) -> 25.5 | S7: =VLOOKUP(P7,LeaseTable,5,FALSE) -> 5 | T7: =VLOOKUP(P7,LeaseTable,6,FALSE) -> 36 | U7: =VLOOKUP(P7,LeaseTable,8,FALSE) -> 0.05 | V7: =VLOOKUP(P7,LeaseTable,9,FALSE) -> 2 | W7: =VLOOKUP(P7,LeaseTable,4,FALSE) -> 0.65 | X7: =R7*(W7*RenewDiscount+(1-W7)) -> 24.67125 | Y7: =IF(J7="","",EOMONTH(DATE(YEAR(CloseDate)+IF(J7>MONTH(CloseDate),0,1),J7,1),0)) -> 46326
A8: =RANK(F8,$F$5:$F$32) -> 4 | B8: 4 | C8: Pinnacle Wealth Advisors | D8: 320 | E8: 3 | F8: 11000 | G8: 20.25 | H8: =F8*G8 -> 222750 | I8: 0.02 | J8: 1 | K8: 45292 | L8: 47118 | M8: 1x3yr | N8: Occupied | O8: =DATEDIF(CloseDate,L8,"m")+1 -> 29 | P8: =LOOKUP(F8,{0,2000,5000,15000}) -> 5000 | Q8: =VLOOKUP(P8,LeaseTable,2,FALSE) -> 5,000-15,000 | R8: =VLOOKUP(P8,LeaseTable,3,FALSE) -> 25.5 | S8: =VLOOKUP(P8,LeaseTable,5,FALSE) -> 5 | T8: =VLOOKUP(P8,LeaseTable,6,FALSE) -> 36 | U8: =VLOOKUP(P8,LeaseTable,8,FALSE) -> 0.05 | V8: =VLOOKUP(P8,LeaseTable,9,FALSE) -> 2 | W8: =VLOOKUP(P8,LeaseTable,4,FALSE) -> 0.65 | X8: =R8*(W8*RenewDiscount+(1-W8)) -> 24.67125 | Y8: =IF(J8="","",EOMONTH(DATE(YEAR(CloseDate)+IF(J8>MONTH(CloseDate),0,1),J8,1),0)) -> 46418
A9: =RANK(F9,$F$5:$F$32) -> 5 | B9: 5 | C9: TechBridge Solutions | D9: 410 | E9: 4 | F9: 10500 | G9: 21.75 | H9: =F9*G9 -> 228375 | I9: 0.03 | J9: 7 | K9: 45839 | L9: 47664 | M9: None | N9: Occupied | O9: =DATEDIF(CloseDate,L9,"m")+1 -> 46 | P9: =LOOKUP(F9,{0,2000,5000,15000}) -> 5000 | Q9: =VLOOKUP(P9,LeaseTable,2,FALSE) -> 5,000-15,000 | R9: =VLOOKUP(P9,LeaseTable,3,FALSE) -> 25.5 | S9: =VLOOKUP(P9,LeaseTable,5,FALSE) -> 5 | T9: =VLOOKUP(P9,LeaseTable,6,FALSE) -> 36 | U9: =VLOOKUP(P9,LeaseTable,8,FALSE) -> 0.05 | V9: =VLOOKUP(P9,LeaseTable,9,FALSE) -> 2 | W9: =VLOOKUP(P9,LeaseTable,4,FALSE) -> 0.65 | X9: =R9*(W9*RenewDiscount+(1-W9)) -> 24.67125 | Y9: =IF(J9="","",EOMONTH(DATE(YEAR(CloseDate)+IF(J9>MONTH(CloseDate),0,1),J9,1),0)) -> 46599
A10: =RANK(F10,$F$5:$F$32) -> 12 | B10: 6 | C10: Brightpath Insurance | D10: 330 | E10: 3 | F10: 7900 | G10: 20.75 | H10: =F10*G10 -> 163925 | I10: 0.025 | J10: 3 | K10: 43525 | L10: 47177 | M10: 1x5yr | N10: Occupied | O10: =DATEDIF(CloseDate,L10,"m")+1 -> 30 | P10: =LOOKUP(F10,{0,2000,5000,15000}) -> 5000 | Q10: =VLOOKUP(P10,LeaseTable,2,FALSE) -> 5,000-15,000 | R10: =VLOOKUP(P10,LeaseTable,3,FALSE) -> 25.5 | S10: =VLOOKUP(P10,LeaseTable,5,FALSE) -> 5 | T10: =VLOOKUP(P10,LeaseTable,6,FALSE) -> 36 | U10: =VLOOKUP(P10,LeaseTable,8,FALSE) -> 0.05 | V10: =VLOOKUP(P10,LeaseTable,9,FALSE) -> 2 | W10: =VLOOKUP(P10,LeaseTable,4,FALSE) -> 0.65 | X10: =R10*(W10*RenewDiscount+(1-W10)) -> 24.67125 | Y10: =IF(J10="","",EOMONTH(DATE(YEAR(CloseDate)+IF(J10>MONTH(CloseDate),0,1),J10,1),0)) -> 46477
A11: =RANK(F11,$F$5:$F$32) -> 6 | B11: 7 | C11: Caldwell Consulting Group | D11: 420 | E11: 4 | F11: 9500 | G11: 20.5 | H11: =F11*G11 -> 194750 | I11: 0.02 | J11: 9 | K11: 44440 | L11: 48091 | M11: 1x5yr | N11: Occupied | O11: =DATEDIF(CloseDate,L11,"m")+1 -> 61 | P11: =LOOKUP(F11,{0,2000,5000,15000}) -> 5000 | Q11: =VLOOKUP(P11,LeaseTable,2,FALSE) -> 5,000-15,000 | R11: =VLOOKUP(P11,LeaseTable,3,FALSE) -> 25.5 | S11: =VLOOKUP(P11,LeaseTable,5,FALSE) -> 5 | T11: =VLOOKUP(P11,LeaseTable,6,FALSE) -> 36 | U11: =VLOOKUP(P11,LeaseTable,8,FALSE) -> 0.05 | V11: =VLOOKUP(P11,LeaseTable,9,FALSE) -> 2 | W11: =VLOOKUP(P11,LeaseTable,4,FALSE) -> 0.65 | X11: =R11*(W11*RenewDiscount+(1-W11)) -> 24.67125 | Y11: =IF(J11="","",EOMONTH(DATE(YEAR(CloseDate)+IF(J11>MONTH(CloseDate),0,1),J11,1),0)) -> 46295
A12: =RANK(F12,$F$5:$F$32) -> 10 | B12: 8 | C12: Queen City Accounting | D12: 210 | E12: 2 | F12: 8500 | G12: 19.75 | H12: =F12*G12 -> 167875 | I12: 0.025 | J12: 2 | K12: 44958 | L12: 46783 | M12: None | N12: Occupied | O12: =DATEDIF(CloseDate,L12,"m")+1 -> 18 | P12: =LOOKUP(F12,{0,2000,5000,15000}) -> 5000 | Q12: =VLOOKUP(P12,LeaseTable,2,FALSE) -> 5,000-15,000 | R12: =VLOOKUP(P12,LeaseTable,3,FALSE) -> 25.5 | S12: =VLOOKUP(P12,LeaseTable,5,FALSE) -> 5 | T12: =VLOOKUP(P12,LeaseTable,6,FALSE) -> 36 | U12: =VLOOKUP(P12,LeaseTable,8,FALSE) -> 0.05 | V12: =VLOOKUP(P12,LeaseTable,9,FALSE) -> 2 | W12: =VLOOKUP(P12,LeaseTable,4,FALSE) -> 0.65 | X12: =R12*(W12*RenewDiscount+(1-W12)) -> 24.67125 | Y12: =IF(J12="","",EOMONTH(DATE(YEAR(CloseDate)+IF(J12>MONTH(CloseDate),0,1),J12,1),0)) -> 46446
A13: =RANK(F13,$F$5:$F$32) -> 13 | B13: 9 | C13: Monarch Marketing Group | D13: 340 | E13: 3 | F13: 7800 | G13: 21 | H13: =F13*G13 -> 163800 | I13: 0.025 | J13: 5 | K13: 43586 | L13: 47238 | M13: 1x3yr | N13: Occupied | O13: =DATEDIF(CloseDate,L13,"m")+1 -> 32 | P13: =LOOKUP(F13,{0,2000,5000,15000}) -> 5000 | Q13: =VLOOKUP(P13,LeaseTable,2,FALSE) -> 5,000-15,000 | R13: =VLOOKUP(P13,LeaseTable,3,FALSE) -> 25.5 | S13: =VLOOKUP(P13,LeaseTable,5,FALSE) -> 5 | T13: =VLOOKUP(P13,LeaseTable,6,FALSE) -> 36 | U13: =VLOOKUP(P13,LeaseTable,8,FALSE) -> 0.05 | V13: =VLOOKUP(P13,LeaseTable,9,FALSE) -> 2 | W13: =VLOOKUP(P13,LeaseTable,4,FALSE) -> 0.65 | X13: =R13*(W13*RenewDiscount+(1-W13)) -> 24.67125 | Y13: =IF(J13="","",EOMONTH(DATE(YEAR(CloseDate)+IF(J13>MONTH(CloseDate),0,1),J13,1),0)) -> 46538
A14: =RANK(F14,$F$5:$F$32) -> 15 | B14: 10 | C14: Davidson & Reed Architects | D14: 430 | E14: 4 | F14: 7200 | G14: 20.75 | H14: =F14*G14 -> 149400 | I14: 0.02 | J14: 12 | K14: 43435 | L14: 47087 | M14: None | N14: Occupied | O14: =DATEDIF(CloseDate,L14,"m")+1 -> 27 | P14: =LOOKUP(F14,{0,2000,5000,15000}) -> 5000 | Q14: =VLOOKUP(P14,LeaseTable,2,FALSE) -> 5,000-15,000 | R14: =VLOOKUP(P14,LeaseTable,3,FALSE) -> 25.5 | S14: =VLOOKUP(P14,LeaseTable,5,FALSE) -> 5 | T14: =VLOOKUP(P14,LeaseTable,6,FALSE) -> 36 | U14: =VLOOKUP(P14,LeaseTable,8,FALSE) -> 0.05 | V14: =VLOOKUP(P14,LeaseTable,9,FALSE) -> 2 | W14: =VLOOKUP(P14,LeaseTable,4,FALSE) -> 0.65 | X14: =R14*(W14*RenewDiscount+(1-W14)) -> 24.67125 | Y14: =IF(J14="","",EOMONTH(DATE(YEAR(CloseDate)+IF(J14>MONTH(CloseDate),0,1),J14,1),0)) -> 46387
A15: =RANK(F15,$F$5:$F$32) -> 16 | B15: 11 | C15: Greenway Environmental | D15: 220 | E15: 2 | F15: 6800 | G15: 19.5 | H15: =F15*G15 -> 132600 | I15: 0.025 | J15: 8 | K15: 43678 | L15: 47330 | M15: None | N15: Occupied | O15: =DATEDIF(CloseDate,L15,"m")+1 -> 36 | P15: =LOOKUP(F15,{0,2000,5000,15000}) -> 5000 | Q15: =VLOOKUP(P15,LeaseTable,2,FALSE) -> 5,000-15,000 | R15: =VLOOKUP(P15,LeaseTable,3,FALSE) -> 25.5 | S15: =VLOOKUP(P15,LeaseTable,5,FALSE) -> 5 | T15: =VLOOKUP(P15,LeaseTable,6,FALSE) -> 36 | U15: =VLOOKUP(P15,LeaseTable,8,FALSE) -> 0.05 | V15: =VLOOKUP(P15,LeaseTable,9,FALSE) -> 2 | W15: =VLOOKUP(P15,LeaseTable,4,FALSE) -> 0.65 | X15: =R15*(W15*RenewDiscount+(1-W15)) -> 24.67125 | Y15: =IF(J15="","",EOMONTH(DATE(YEAR(CloseDate)+IF(J15>MONTH(CloseDate),0,1),J15,1),0)) -> 46630
A16: =RANK(F16,$F$5:$F$32) -> 18 | B16: 12 | C16: Trellis HR Solutions | D16: 510 | E16: 5 | F16: 6200 | G16: 22.25 | H16: =F16*G16 -> 137950 | I16: 0.025 | J16: 6 | K16: 45078 | L16: 47634 | M16: 1x3yr | N16: Occupied | O16: =DATEDIF(CloseDate,L16,"m")+1 -> 46 | P16: =LOOKUP(F16,{0,2000,5000,15000}) -> 5000 | Q16: =VLOOKUP(P16,LeaseTable,2,FALSE) -> 5,000-15,000 | R16: =VLOOKUP(P16,LeaseTable,3,FALSE) -> 25.5 | S16: =VLOOKUP(P16,LeaseTable,5,FALSE) -> 5 | T16: =VLOOKUP(P16,LeaseTable,6,FALSE) -> 36 | U16: =VLOOKUP(P16,LeaseTable,8,FALSE) -> 0.05 | V16: =VLOOKUP(P16,LeaseTable,9,FALSE) -> 2 | W16: =VLOOKUP(P16,LeaseTable,4,FALSE) -> 0.65 | X16: =R16*(W16*RenewDiscount+(1-W16)) -> 24.67125 | Y16: =IF(J16="","",EOMONTH(DATE(YEAR(CloseDate)+IF(J16>MONTH(CloseDate),0,1),J16,1),0)) -> 46568
A17: =RANK(F17,$F$5:$F$32) -> 21 | B17: 13 | C17: Summit Digital Media | D17: 350 | E17: 3 | F17: 5400 | G17: 21.5 | H17: =F17*G17 -> 116100 | I17: 0.03 | J17: 11 | K17: 45231 | L17: 47057 | M17: None | N17: Occupied | O17: =DATEDIF(CloseDate,L17,"m")+1 -> 27 | P17: =LOOKUP(F17,{0,2000,5000,15000}) -> 5000 | Q17: =VLOOKUP(P17,LeaseTable,2,FALSE) -> 5,000-15,000 | R17: =VLOOKUP(P17,LeaseTable,3,FALSE) -> 25.5 | S17: =VLOOKUP(P17,LeaseTable,5,FALSE) -> 5 | T17: =VLOOKUP(P17,LeaseTable,6,FALSE) -> 36 | U17: =VLOOKUP(P17,LeaseTable,8,FALSE) -> 0.05 | V17: =VLOOKUP(P17,LeaseTable,9,FALSE) -> 2 | W17: =VLOOKUP(P17,LeaseTable,4,FALSE) -> 0.65 | X17: =R17*(W17*RenewDiscount+(1-W17)) -> 24.67125 | Y17: =IF(J17="","",EOMONTH(DATE(YEAR(CloseDate)+IF(J17>MONTH(CloseDate),0,1),J17,1),0)) -> 46356
... A23: =RANK(F23,$F$5:$F$32) -> 27 | B23: 19 | C23: Horizon Physical Therapy | D23: 110 | E23: 1 | F23: 2500 | G23: 18.5 | H23: =F23*G23 -> 46250 | I23: 0.02 | J23: 3 | K23: 44986 | L23: 46811 | M23: None | N23: Occupied | O23: =DATEDIF(CloseDate,L23,"m")+1 -> 18 | P23: =LOOKUP(F23,{0,2000,5000,15000}) -> 2000 | Q23: =VLOOKUP(P23,LeaseTable,2,FALSE) -> 2,000-5,000 | R23: =VLOOKUP(P23,LeaseTable,3,FALSE) -> 25 | S23: =VLOOKUP(P23,LeaseTable,5,FALSE) -> 6 | T23: =VLOOKUP(P23,LeaseTable,6,FALSE) -> 32 | U23: =VLOOKUP(P23,LeaseTable,8,FALSE) -> 0.06 | V23: =VLOOKUP(P23,LeaseTable,9,FALSE) -> 2 | W23: =VLOOKUP(P23,LeaseTable,4,FALSE) -> 0.55 | X23: =R23*(W23*RenewDiscount+(1-W23)) -> 24.3125 | Y23: =IF(J23="","",EOMONTH(DATE(YEAR(CloseDate)+IF(J23>MONTH(CloseDate),0,1),J23,1),0)) -> 46477
A24: =RANK(F24,$F$5:$F$32) -> 28 | B24: 20 | C24: SouthPark Dental Associates | D24: 120 | E24: 1 | F24: 1800 | G24: 18 | H24: =F24*G24 -> 32400 | I24: 0.02 | J24: 4 | K24: 44287 | L24: 46112 | M24: None | N24: Ghost | O24: =IF(L24<CloseDate,0,DATEDIF(CloseDate,L24,"m")+1) -> 0 | P24: =LOOKUP(F24,{0,2000,5000,15000}) -> 0 | Q24: =VLOOKUP(P24,LeaseTable,2,FALSE) -> <2,000 | R24: =VLOOKUP(P24,LeaseTable,3,FALSE) -> 24 | S24: =VLOOKUP(P24,LeaseTable,5,FALSE) -> 7 | T24: =VLOOKUP(P24,LeaseTable,6,FALSE) -> 28 | U24: =VLOOKUP(P24,LeaseTable,8,FALSE) -> 0.06 | V24: =VLOOKUP(P24,LeaseTable,9,FALSE) -> 3 | W24: =VLOOKUP(P24,LeaseTable,4,FALSE) -> 0.5 | X24: =R24*(W24*RenewDiscount+(1-W24)) -> 23.4 | Y24: =IF(J24="","",EOMONTH(DATE(YEAR(CloseDate)+IF(J24>MONTH(CloseDate),0,1),J24,1),0)) -> 46507
A25: =RANK(F25,$F$5:$F$32) -> 10 | B25: 21 | C25: Vacant — Suite 130 | D25: 130 | E25: 1 | F25: 8500 | G25: 0 | H25: =F25*G25 -> 0 | M25: — | N25: Vacant | O25: 3 | P25: =LOOKUP(F25,{0,2000,5000,15000}) -> 5000 | Q25: =VLOOKUP(P25,LeaseTable,2,FALSE) -> 5,000-15,000 | R25: =VLOOKUP(P25,LeaseTable,3,FALSE) -> 25.5 | S25: =VLOOKUP(P25,LeaseTable,5,FALSE) -> 5 | T25: =VLOOKUP(P25,LeaseTable,6,FALSE) -> 36 | U25: =VLOOKUP(P25,LeaseTable,8,FALSE) -> 0.05 | V25: =VLOOKUP(P25,LeaseTable,9,FALSE) -> 2 | W25: =VLOOKUP(P25,LeaseTable,4,FALSE) -> 0.65 | X25: =R25*(W25*RenewDiscount+(1-W25)) -> 24.67125
A26: =RANK(F26,$F$5:$F$32) -> 17 | B26: 22 | C26: Vacant — Suite 250 | D26: 250 | E26: 2 | F26: 6400 | G26: 0 | H26: =F26*G26 -> 0 | M26: — | N26: Vacant | O26: 4 | P26: =LOOKUP(F26,{0,2000,5000,15000}) -> 5000 | Q26: =VLOOKUP(P26,LeaseTable,2,FALSE) -> 5,000-15,000 | R26: =VLOOKUP(P26,LeaseTable,3,FALSE) -> 25.5 | S26: =VLOOKUP(P26,LeaseTable,5,FALSE) -> 5 | T26: =VLOOKUP(P26,LeaseTable,6,FALSE) -> 36 | U26: =VLOOKUP(P26,LeaseTable,8,FALSE) -> 0.05 | V26: =VLOOKUP(P26,LeaseTable,9,FALSE) -> 2 | W26: =VLOOKUP(P26,LeaseTable,4,FALSE) -> 0.65 | X26: =R26*(W26*RenewDiscount+(1-W26)) -> 24.67125
A27: =RANK(F27,$F$5:$F$32) -> 20 | B27: 23 | C27: Vacant — Suite 360 | D27: 360 | E27: 3 | F27: 5800 | G27: 0 | H27: =F27*G27 -> 0 | M27: — | N27: Vacant | O27: 5 | P27: =LOOKUP(F27,{0,2000,5000,15000}) -> 5000 | Q27: =VLOOKUP(P27,LeaseTable,2,FALSE) -> 5,000-15,000 | R27: =VLOOKUP(P27,LeaseTable,3,FALSE) -> 25.5 | S27: =VLOOKUP(P27,LeaseTable,5,FALSE) -> 5 | T27: =VLOOKUP(P27,LeaseTable,6,FALSE) -> 36 | U27: =VLOOKUP(P27,LeaseTable,8,FALSE) -> 0.05 | V27: =VLOOKUP(P27,LeaseTable,9,FALSE) -> 2 | W27: =VLOOKUP(P27,LeaseTable,4,FALSE) -> 0.65 | X27: =R27*(W27*RenewDiscount+(1-W27)) -> 24.67125
A28: =RANK(F28,$F$5:$F$32) -> 7 | B28: 24 | C28: Vacant — Suite 450 | D28: 450 | E28: 4 | F28: 9200 | G28: 0 | H28: =F28*G28 -> 0 | M28: — | N28: Vacant | O28: 6 | P28: =LOOKUP(F28,{0,2000,5000,15000}) -> 5000 | Q28: =VLOOKUP(P28,LeaseTable,2,FALSE) -> 5,000-15,000 | R28: =VLOOKUP(P28,LeaseTable,3,FALSE) -> 25.5 | S28: =VLOOKUP(P28,LeaseTable,5,FALSE) -> 5 | T28: =VLOOKUP(P28,LeaseTable,6,FALSE) -> 36 | U28: =VLOOKUP(P28,LeaseTable,8,FALSE) -> 0.05 | V28: =VLOOKUP(P28,LeaseTable,9,FALSE) -> 2 | W28: =VLOOKUP(P28,LeaseTable,4,FALSE) -> 0.65 | X28: =R28*(W28*RenewDiscount+(1-W28)) -> 24.67125
A29: =RANK(F29,$F$5:$F$32) -> 14 | B29: 25 | C29: Vacant — Suite 460 | D29: 460 | E29: 4 | F29: 7500 | G29: 0 | H29: =F29*G29 -> 0 | M29: — | N29: Vacant | O29: 7 | P29: =LOOKUP(F29,{0,2000,5000,15000}) -> 5000 | Q29: =VLOOKUP(P29,LeaseTable,2,FALSE) -> 5,000-15,000 | R29: =VLOOKUP(P29,LeaseTable,3,FALSE) -> 25.5 | S29: =VLOOKUP(P29,LeaseTable,5,FALSE) -> 5 | T29: =VLOOKUP(P29,LeaseTable,6,FALSE) -> 36 | U29: =VLOOKUP(P29,LeaseTable,8,FALSE) -> 0.05 | V29: =VLOOKUP(P29,LeaseTable,9,FALSE) -> 2 | W29: =VLOOKUP(P29,LeaseTable,4,FALSE) -> 0.65 | X29: =R29*(W29*RenewDiscount+(1-W29)) -> 24.67125
A30: =RANK(F30,$F$5:$F$32) -> 9 | B30: 26 | C30: Vacant — Suite 540 | D30: 540 | E30: 5 | F30: 8800 | G30: 0 | H30: =F30*G30 -> 0 | M30: — | N30: Vacant | O30: 9 | P30: =LOOKUP(F30,{0,2000,5000,15000}) -> 5000 | Q30: =VLOOKUP(P30,LeaseTable,2,FALSE) -> 5,000-15,000 | R30: =VLOOKUP(P30,LeaseTable,3,FALSE) -> 25.5 | S30: =VLOOKUP(P30,LeaseTable,5,FALSE) -> 5 | T30: =VLOOKUP(P30,LeaseTable,6,FALSE) -> 36 | U30: =VLOOKUP(P30,LeaseTable,8,FALSE) -> 0.05 | V30: =VLOOKUP(P30,LeaseTable,9,FALSE) -> 2 | W30: =VLOOKUP(P30,LeaseTable,4,FALSE) -> 0.65 | X30: =R30*(W30*RenewDiscount+(1-W30)) -> 24.67125
A31: =RANK(F31,$F$5:$F$32) -> 18 | B31: 27 | C31: Vacant — Suite 550 | D31: 550 | E31: 5 | F31: 6200 | G31: 0 | H31: =F31*G31 -> 0 | M31: — | N31: Vacant | O31: 10 | P31: =LOOKUP(F31,{0,2000,5000,15000}) -> 5000 | Q31: =VLOOKUP(P31,LeaseTable,2,FALSE) -> 5,000-15,000 | R31: =VLOOKUP(P31,LeaseTable,3,FALSE) -> 25.5 | S31: =VLOOKUP(P31,LeaseTable,5,FALSE) -> 5 | T31: =VLOOKUP(P31,LeaseTable,6,FALSE) -> 36 | U31: =VLOOKUP(P31,LeaseTable,8,FALSE) -> 0.05 | V31: =VLOOKUP(P31,LeaseTable,9,FALSE) -> 2 | W31: =VLOOKUP(P31,LeaseTable,4,FALSE) -> 0.65 | X31: =R31*(W31*RenewDiscount+(1-W31)) -> 24.67125
A32: =RANK(F32,$F$5:$F$32) -> 7 | B32: 28 | C32: Vacant — Suite 830 | D32: 830 | E32: 8 | F32: 9200 | G32: 0 | H32: =F32*G32 -> 0 | M32: — | N32: Vacant | O32: 12 | P32: =LOOKUP(F32,{0,2000,5000,15000}) -> 5000 | Q32: =VLOOKUP(P32,LeaseTable,2,FALSE) -> 5,000-15,000 | R32: =VLOOKUP(P32,LeaseTable,3,FALSE) -> 25.5 | S32: =VLOOKUP(P32,LeaseTable,5,FALSE) -> 5 | T32: =VLOOKUP(P32,LeaseTable,6,FALSE) -> 36 | U32: =VLOOKUP(P32,LeaseTable,8,FALSE) -> 0.05 | V32: =VLOOKUP(P32,LeaseTable,9,FALSE) -> 2 | W32: =VLOOKUP(P32,LeaseTable,4,FALSE) -> 0.65 | X32: =R32*(W32*RenewDiscount+(1-W32)) -> 24.67125
B34: TOTAL | C34: 28 entries | F34: =SUM(F5:F32) -> 280000 | G34: =H34/F34 -> 15.903036 | H34: =SUM(H5:H32) -> 4452850 | L34: {=SUMPRODUCT((L5:L32)*(H5:H32)*(N5:N32<>"Vacant"))/H34} -> 46928.587 | X34: =SUMPRODUCT(X5:X32,F5:F32)/F34 -> 24.676044
B36: SF check vs Building SF: | F36: =F34-BldgSF -> 0 | G36: =IF(F36=0,"OK","CHECK") -> OK
B38: SPEC SUITES (Meridian re-demise — 76,000 SF, not additive)
B40: # | C40: Suite | D40: Floor | F40: SF | O40: Commence Mo# | T40: TI $/SF | U40: LC % | V40: Free New | X40: Rent $/SF
B41: 29 | C41: Suite 610 | D41: 6 | F41: 14000 | O41: 12 | P41: Adjusted per VP feedback (email 9) | T41: =SpecTI -> 40 | U41: 0.05 | V41: 2 | X41: 26
B42: 30 | C42: Suite 620 | D42: 6 | F42: 13000 | O42: 12 | P42: Adjusted per VP feedback (email 9) | T42: =SpecTI -> 40 | U42: 0.05 | V42: 2 | X42: 26
B43: 31 | C43: Suite 710 | D43: 7 | F43: 13000 | O43: 14 | P43: Adjusted per VP feedback (email 9) | T43: =SpecTI -> 40 | U43: 0.05 | V43: 2 | X43: 26
B44: 32 | C44: Suite 720 | D44: 7 | F44: 12000 | O44: 14 | P44: Adjusted per VP feedback (email 9) | T44: =SpecTI -> 40 | U44: 0.05 | V44: 2 | X44: 26
B45: 33 | C45: Suite 810 | D45: 8 | F45: 12500 | O45: 16 | P45: Adjusted per VP feedback (email 9) | T45: =SpecTI -> 40 | U45: 0.05 | V45: 2 | X45: 26
B46: 34 | C46: Suite 820 | D46: 8 | F46: 11500 | O46: 16 | P46: Adjusted per VP feedback (email 9) | T46: =SpecTI -> 40 | U46: 0.05 | V46: 2 | X46: 26
C47: Total (= Meridian 76,000) | F47: =SUM(F41:F46) -> 76000

Sheet Rent Roll Calc
A1: SouthPark Centre — Rent Roll Calc
A3: Month # | D3: 0 | E3: =D3+1 -> 1 | F3: =E3+1 -> 2 | G3: =F3+1 -> 3 | H3: =G3+1 -> 4 | I3: =H3+1 -> 5 | J3: =I3+1 -> 6 | K3: =J3+1 -> 7 | L3: =K3+1 -> 8 | ... BX3: =BW3+1 -> 72
A4: Period End | D4: =EOMONTH(CloseDate,D3) -> 46265 | E4: =EOMONTH(CloseDate,E3) -> 46295 | F4: =EOMONTH(CloseDate,F3) -> 46326 | G4: =EOMONTH(CloseDate,G3) -> 46356 | H4: =EOMONTH(CloseDate,H3) -> 46387 | I4: =EOMONTH(CloseDate,I3) -> 46418 | J4: =EOMONTH(CloseDate,J3) -> 46446 | K4: =EOMONTH(CloseDate,K3) -> 46477 | ... BX4: =EOMONTH(CloseDate,BX3) -> 48457
A5: Year | D5: =INT((D3-1)/12)+1 -> 0 | E5: =INT((E3-1)/12)+1 -> 1 | F5: =INT((F3-1)/12)+1 -> 1 | G5: =INT((G3-1)/12)+1 -> 1 | H5: =INT((H3-1)/12)+1 -> 1 | I5: =INT((I3-1)/12)+1 -> 1 | J5: =INT((J3-1)/12)+1 -> 1 | K5: =INT((K3-1)/12)+1 -> 1 | ... BX5: =INT((BX3-1)/12)+1 -> 6
A6: Rent Growth Index | D6: =IF(MONTH(D4)=1,(1+RentGrowth),1) -> 1 | E6: =IF(MONTH(E4)=1,D6*(1+RentGrowth),D6) -> 1 | F6: =IF(MONTH(F4)=1,E6*(1+RentGrowth),E6) -> 1 | G6: =IF(MONTH(G4)=1,F6*(1+RentGrowth),F6) -> 1 | H6: =IF(MONTH(H4)=1,G6*(1+RentGrowth),G6) -> 1 | I6: =IF(MONTH(I4)=1,H6*(1+RentGrowth),H6) -> 1.027 | J6: =IF(MONTH(J4)=1,I6*(1+RentGrowth),I6) -> 1.027 | K6: =IF(MONTH(K4)=1,J6*(1+RentGrowth),J6) -> 1.027 | L6: =IF(MONTH(L4)=1,K6*(1+RentGrowth),K6) -> 1.027 | ... BX6: =IF(MONTH(BX4)=1,BW6*(1+RentGrowth),BW6) -> 1.1733367
A7: Expense Growth Index | D7: =IF(MONTH(D4)=1,(1+ExpGrowth),1) -> 1 | E7: =IF(MONTH(E4)=1,D7*(1+ExpGrowth),D7) -> 1 | F7: =IF(MONTH(F4)=1,E7*(1+ExpGrowth),E7) -> 1 | G7: =IF(MONTH(G4)=1,F7*(1+ExpGrowth),F7) -> 1 | H7: =IF(MONTH(H4)=1,G7*(1+ExpGrowth),G7) -> 1 | I7: =IF(MONTH(I4)=1,H7*(1+ExpGrowth),H7) -> 1.027 | J7: =IF(MONTH(J4)=1,I7*(1+ExpGrowth),I7) -> 1.027 | K7: =IF(MONTH(K4)=1,J7*(1+ExpGrowth),J7) -> 1.027 | L7: =IF(MONTH(L4)=1,K7*(1+ExpGrowth),K7) -> 1.027 | ... BX7: =IF(MONTH(BX4)=1,BW7*(1+ExpGrowth),BW7) -> 1.1733367
A9: ='Rent Roll'!C5 -> Meridian Financial Group | B9: =INDEX('Rent Roll'!$F$5:$F$46,MATCH('Rent Roll Calc'!A9,'Rent Roll'!$C$5:$C$46,0)) -> 76000
B10: Occupancy Flag | D10: =IF(AND('Rent Roll'!$N$5<>"Ghost",D$4<='Rent Roll'!$L$5),1,0) -> 1 | E10: =IF(AND('Rent Roll'!$N$5<>"Ghost",E$4<='Rent Roll'!$L$5),1,0) -> 1 | F10: =IF(AND('Rent Roll'!$N$5<>"Ghost",F$4<='Rent Roll'!$L$5),1,0) -> 1 | G10: =IF(AND('Rent Roll'!$N$5<>"Ghost",G$4<='Rent Roll'!$L$5),1,0) -> 0 | H10: =IF(AND('Rent Roll'!$N$5<>"Ghost",H$4<='Rent Roll'!$L$5),1,0) -> 0 | I10: =IF(AND('Rent Roll'!$N$5<>"Ghost",I$4<='Rent Roll'!$L$5),1,0) -> 0 | J10: =IF(AND('Rent Roll'!$N$5<>"Ghost",J$4<='Rent Roll'!$L$5),1,0) -> 0 | K10: =IF(AND('Rent Roll'!$N$5<>"Ghost",K$4<='Rent Roll'!$L$5),1,0) -> 0 | ... BX10: =IF(AND('Rent Roll'!$N$5<>"Ghost",BX$4<='Rent Roll'!$L$5),1,0) -> 0
B11: In-Place Rent | D11: =IF(D10=1,'Rent Roll'!$H$5/12*(1+'Rent Roll'!$I$5)^IF(D$4<'Rent Roll'!$Y$5,0,YEAR(D$4)-YEAR('Rent Roll'!$Y$5)+1),0) -> 123500 | E11: =IF(E10=1,'Rent Roll'!$H$5/12*(1+'Rent Roll'!$I$5)^IF(E$4<'Rent Roll'!$Y$5,0,YEAR(E$4)-YEAR('Rent Roll'!$Y$5)+1),0) -> 123500 | F11: =IF(F10=1,'Rent Roll'!$H$5/12*(1+'Rent Roll'!$I$5)^IF(F$4<'Rent Roll'!$Y$5,0,YEAR(F$4)-YEAR('Rent Roll'!$Y$5)+1),0) -> 123500 | G11: =IF(G10=1,'Rent Roll'!$H$5/12*(1+'Rent Roll'!$I$5)^IF(G$4<'Rent Roll'!$Y$5,0,YEAR(G$4)-YEAR('Rent Roll'!$Y$5)+1),0) -> 0 | H11: =IF(H10=1,'Rent Roll'!$H$5/12*(1+'Rent Roll'!$I$5)^IF(H$4<'Rent Roll'!$Y$5,0,YEAR(H$4)-YEAR('Rent Roll'!$Y$5)+1),0) -> 0 | I11: =IF(I10=1,'Rent Roll'!$H$5/12*(1+'Rent Roll'!$I$5)^IF(I$4<'Rent Roll'!$Y$5,0,YEAR(I$4)-YEAR('Rent Roll'!$Y$5)+1),0) -> 0 | J11: =IF(J10=1,'Rent Roll'!$H$5/12*(1+'Rent Roll'!$I$5)^IF(J$4<'Rent Roll'!$Y$5,0,YEAR(J$4)-YEAR('Rent Roll'!$Y$5)+1),0) -> 0 | K11: =IF(K10=1,'Rent Roll'!$H$5/12*(1+'Rent Roll'!$I$5)^IF(K$4<'Rent Roll'!$Y$5,0,YEAR(K$4)-YEAR('Rent Roll'!$Y$5)+1),0) -> 0 | ... BX11: =IF(BX10=1,'Rent Roll'!$H$5/12*(1+'Rent Roll'!$I$5)^IF(BX$4<'Rent Roll'!$Y$5,0,YEAR(BX$4)-YEAR('Rent Roll'!$Y$5)+1),0) -> 0
B12: Re-Let Flag | D12: =0 -> 0 | E12: =0 -> 0 | F12: =0 -> 0 | G12: =0 -> 0 | H12: =0 -> 0 | I12: =0 -> 0 | J12: =0 -> 0 | K12: =0 -> 0 | ... BX12: =0 -> 0
B13: Re-Let Rent (gross) | D13: =0 -> 0 | E13: =0 -> 0 | F13: =0 -> 0 | G13: =0 -> 0 | H13: =0 -> 0 | I13: =0 -> 0 | J13: =0 -> 0 | K13: =0 -> 0 | ... BX13: =0 -> 0
B14: Free Rent Adj | D14: =0 -> 0 | E14: =0 -> 0 | F14: =0 -> 0 | G14: =0 -> 0 | H14: =0 -> 0 | I14: =0 -> 0 | J14: =0 -> 0 | K14: =0 -> 0 | ... BX14: =0 -> 0
B15: Net Base Rent | D15: =D11+D13+D14 -> 123500 | E15: =E11+E13+E14 -> 123500 | F15: =F11+F13+F14 -> 123500 | G15: =G11+G13+G14 -> 0 | H15: =H11+H13+H14 -> 0 | I15: =I11+I13+I14 -> 0 | J15: =J11+J13+J14 -> 0 | K15: =K11+K13+K14 -> 0 | ... BX15: =BX11+BX13+BX14 -> 0
B16: Opex Recovery (NNN) | D16: =IF(OR(D10=1,D12=1),'Rent Roll'!$F$5/BldgSF*ReimbPool/12*D$7,0) -> 66310 | E16: =IF(OR(E10=1,E12=1),'Rent Roll'!$F$5/BldgSF*ReimbPool/12*E$7,0) -> 66310 | F16: =IF(OR(F10=1,F12=1),'Rent Roll'!$F$5/BldgSF*ReimbPool/12*F$7,0) -> 66310 | G16: =IF(OR(G10=1,G12=1),'Rent Roll'!$F$5/BldgSF*ReimbPool/12*G$7,0) -> 0 | H16: =IF(OR(H10=1,H12=1),'Rent Roll'!$F$5/BldgSF*ReimbPool/12*H$7,0) -> 0 | I16: =IF(OR(I10=1,I12=1),'Rent Roll'!$F$5/BldgSF*ReimbPool/12*I$7,0) -> 0 | J16: =IF(OR(J10=1,J12=1),'Rent Roll'!$F$5/BldgSF*ReimbPool/12*J$7,0) -> 0 | K16: =IF(OR(K10=1,K12=1),'Rent Roll'!$F$5/BldgSF*ReimbPool/12*K$7,0) -> 0 | ... BX16: =IF(OR(BX10=1,BX12=1),'Rent Roll'!$F$5/BldgSF*ReimbPool/12*BX$7,0) -> 0
B17: TI (capital) | D17: =0 -> 0 | E17: =0 -> 0 | F17: =0 -> 0 | G17: =0 -> 0 | H17: =0 -> 0 | I17: =0 -> 0 | J17: =0 -> 0 | K17: =0 -> 0 | ... BX17: =0 -> 0
B18: LC (capital) | D18: =0 -> 0 | E18: =0 -> 0 | F18: =0 -> 0 | G18: =0 -> 0 | H18: =0 -> 0 | I18: =0 -> 0 | J18: =0 -> 0 | K18: =0 -> 0 | ... BX18: =0 -> 0
A19: ='Rent Roll'!C6 -> Southeast Regional Health | B19: =INDEX('Rent Roll'!$F$5:$F$46,MATCH('Rent Roll Calc'!A19,'Rent Roll'!$C$5:$C$46,0)) -> 24000
B20: Occupancy Flag | D20: =IF(AND('Rent Roll'!$N$6<>"Ghost",D$4<='Rent Roll'!$L$6),1,0) -> 1 | E20: =IF(AND('Rent Roll'!$N$6<>"Ghost",E$4<='Rent Roll'!$L$6),1,0) -> 1 | F20: =IF(AND('Rent Roll'!$N$6<>"Ghost",F$4<='Rent Roll'!$L$6),1,0) -> 1 | G20: =IF(AND('Rent Roll'!$N$6<>"Ghost",G$4<='Rent Roll'!$L$6),1,0) -> 1 | H20: =IF(AND('Rent Roll'!$N$6<>"Ghost",H$4<='Rent Roll'!$L$6),1,0) -> 1 | I20: =IF(AND('Rent Roll'!$N$6<>"Ghost",I$4<='Rent Roll'!$L$6),1,0) -> 1 | J20: =IF(AND('Rent Roll'!$N$6<>"Ghost",J$4<='Rent Roll'!$L$6),1,0) -> 1 | K20: =IF(AND('Rent Roll'!$N$6<>"Ghost",K$4<='Rent Roll'!$L$6),1,0) -> 1 | ... BX20: =IF(AND('Rent Roll'!$N$6<>"Ghost",BX$4<='Rent Roll'!$L$6),1,0) -> 0
B21: In-Place Rent | D21: =IF(D20=1,'Rent Roll'!$H$6/12*(1+'Rent Roll'!$I$6)^IF(D$4<'Rent Roll'!$Y$6,0,YEAR(D$4)-YEAR('Rent Roll'!$Y$6)+1),0) -> 43000 | E21: =IF(E20=1,'Rent Roll'!$H$6/12*(1+'Rent Roll'!$I$6)^IF(E$4<'Rent Roll'!$Y$6,0,YEAR(E$4)-YEAR('Rent Roll'!$Y$6)+1),0) -> 43000 | F21: =IF(F20=1,'Rent Roll'!$H$6/12*(1+'Rent Roll'!$I$6)^IF(F$4<'Rent Roll'!$Y$6,0,YEAR(F$4)-YEAR('Rent Roll'!$Y$6)+1),0) -> 43000 | G21: =IF(G20=1,'Rent Roll'!$H$6/12*(1+'Rent Roll'!$I$6)^IF(G$4<'Rent Roll'!$Y$6,0,YEAR(G$4)-YEAR('Rent Roll'!$Y$6)+1),0) -> 43000 | H21: =IF(H20=1,'Rent Roll'!$H$6/12*(1+'Rent Roll'!$I$6)^IF(H$4<'Rent Roll'!$Y$6,0,YEAR(H$4)-YEAR('Rent Roll'!$Y$6)+1),0) -> 43000 | I21: =IF(I20=1,'Rent Roll'!$H$6/12*(1+'Rent Roll'!$I$6)^IF(I$4<'Rent Roll'!$Y$6,0,YEAR(I$4)-YEAR('Rent Roll'!$Y$6)+1),0) -> 43000 | J21: =IF(J20=1,'Rent Roll'!$H$6/12*(1+'Rent Roll'!$I$6)^IF(J$4<'Rent Roll'!$Y$6,0,YEAR(J$4)-YEAR('Rent Roll'!$Y$6)+1),0) -> 43000 | K21: =IF(K20=1,'Rent Roll'!$H$6/12*(1+'Rent Roll'!$I$6)^IF(K$4<'Rent Roll'!$Y$6,0,YEAR(K$4)-YEAR('Rent Roll'!$Y$6)+1),0) -> 43000 | ... BX21: =IF(BX20=1,'Rent Roll'!$H$6/12*(1+'Rent Roll'!$I$6)^IF(BX$4<'Rent Roll'!$Y$6,0,YEAR(BX$4)-YEAR('Rent Roll'!$Y$6)+1),0) -> 0
B22: Re-Let Flag | D22: =IF(D$4>EOMONTH(CloseDate,'Rent Roll'!$O$6+'Rent Roll'!$S$6-1),1,0) -> 0 | E22: =IF(E$4>EOMONTH(CloseDate,'Rent Roll'!$O$6+'Rent Roll'!$S$6-1),1,0) -> 0 | F22: =IF(F$4>EOMONTH(CloseDate,'Rent Roll'!$O$6+'Rent Roll'!$S$6-1),1,0) -> 0 | G22: =IF(G$4>EOMONTH(CloseDate,'Rent Roll'!$O$6+'Rent Roll'!$S$6-1),1,0) -> 0 | H22: =IF(H$4>EOMONTH(CloseDate,'Rent Roll'!$O$6+'Rent Roll'!$S$6-1),1,0) -> 0 | I22: =IF(I$4>EOMONTH(CloseDate,'Rent Roll'!$O$6+'Rent Roll'!$S$6-1),1,0) -> 0 | J22: =IF(J$4>EOMONTH(CloseDate,'Rent Roll'!$O$6+'Rent Roll'!$S$6-1),1,0) -> 0 | K22: =IF(K$4>EOMONTH(CloseDate,'Rent Roll'!$O$6+'Rent Roll'!$S$6-1),1,0) -> 0 | ... BX22: =IF(BX$4>EOMONTH(CloseDate,'Rent Roll'!$O$6+'Rent Roll'!$S$6-1),1,0) -> 1
B23: Re-Let Rent (gross) | D23: =IF(D22=1,'Rent Roll'!$F$6*'Rent Roll'!$X$6/12*D$6,0) -> 0 | E23: =IF(E22=1,'Rent Roll'!$F$6*'Rent Roll'!$X$6/12*E$6,0) -> 0 | F23: =IF(F22=1,'Rent Roll'!$F$6*'Rent Roll'!$X$6/12*F$6,0) -> 0 | G23: =IF(G22=1,'Rent Roll'!$F$6*'Rent Roll'!$X$6/12*G$6,0) -> 0 | H23: =IF(H22=1,'Rent Roll'!$F$6*'Rent Roll'!$X$6/12*H$6,0) -> 0 | I23: =IF(I22=1,'Rent Roll'!$F$6*'Rent Roll'!$X$6/12*I$6,0) -> 0 | J23: =IF(J22=1,'Rent Roll'!$F$6*'Rent Roll'!$X$6/12*J$6,0) -> 0 | K23: =IF(K22=1,'Rent Roll'!$F$6*'Rent Roll'!$X$6/12*K$6,0) -> 0 | ... BX23: =IF(BX22=1,'Rent Roll'!$F$6*'Rent Roll'!$X$6/12*BX$6,0) -> 56466.83
B24: Free Rent Adj | D24: =IF(AND(D$4>EOMONTH(CloseDate,'Rent Roll'!$O$6+'Rent Roll'!$S$6-1),D$4<=EOMONTH(CloseDate,'Rent Roll'!$O$6+'Rent Roll'!$S$6-1+'Rent Roll'!$V$6)),-D23,0) -> 0 | E24: =IF(AND(E$4>EOMONTH(CloseDate,'Rent Roll'!$O$6+'Rent Roll'!$S$6-1),E$4<=EOMONTH(CloseDate,'Rent Roll'!$O$6+'Rent Roll'!$S$6-1+'Rent Roll'!$V$6)),-E23,0) -> 0 | F24: =IF(AND(F$4>EOMONTH(CloseDate,'Rent Roll'!$O$6+'Rent Roll'!$S$6-1),F$4<=EOMONTH(CloseDate,'Rent Roll'!$O$6+'Rent Roll'!$S$6-1+'Rent Roll'!$V$6)),-F23,0) -> 0 | G24: =IF(AND(G$4>EOMONTH(CloseDate,'Rent Roll'!$O$6+'Rent Roll'!$S$6-1),G$4<=EOMONTH(CloseDate,'Rent Roll'!$O$6+'Rent Roll'!$S$6-1+'Rent Roll'!$V$6)),-G23,0) -> 0 | H24: =IF(AND(H$4>EOMONTH(CloseDate,'Rent Roll'!$O$6+'Rent Roll'!$S$6-1),H$4<=EOMONTH(CloseDate,'Rent Roll'!$O$6+'Rent Roll'!$S$6-1+'Rent Roll'!$V$6)),-H23,0) -> 0 | I24: =IF(AND(I$4>EOMONTH(CloseDate,'Rent Roll'!$O$6+'Rent Roll'!$S$6-1),I$4<=EOMONTH(CloseDate,'Rent Roll'!$O$6+'Rent Roll'!$S$6-1+'Rent Roll'!$V$6)),-I23,0) -> 0 | J24: =IF(AND(J$4>EOMONTH(CloseDate,'Rent Roll'!$O$6+'Rent Roll'!$S$6-1),J$4<=EOMONTH(CloseDate,'Rent Roll'!$O$6+'Rent Roll'!$S$6-1+'Rent Roll'!$V$6)),-J23,0) -> 0 | K24: =IF(AND(K$4>EOMONTH(CloseDate,'Rent Roll'!$O$6+'Rent Roll'!$S$6-1),K$4<=EOMONTH(CloseDate,'Rent Roll'!$O$6+'Rent Roll'!$S$6-1+'Rent Roll'!$V$6)),-K23,0) -> 0 | ... BX24: =IF(AND(BX$4>EOMONTH(CloseDate,'Rent Roll'!$O$6+'Rent Roll'!$S$6-1),BX$4<=EOMONTH(CloseDate,'Rent Roll'!$O$6+'Rent Roll'!$S$6-1+'Rent Roll'!$V$6)),-BX23,0) -> 0
B25: Net Base Rent | D25: =D21+D23+D24 -> 43000 | E25: =E21+E23+E24 -> 43000 | F25: =F21+F23+F24 -> 43000 | G25: =G21+G23+G24 -> 43000 | H25: =H21+H23+H24 -> 43000 | I25: =I21+I23+I24 -> 43000 | J25: =J21+J23+J24 -> 43000 | K25: =K21+K23+K24 -> 43000 | ... BX25: =BX21+BX23+BX24 -> 56466.83
B26: Opex Recovery (NNN) | D26: =IF(OR(D20=1,D22=1),'Rent Roll'!$F$6/BldgSF*ReimbPool/12*D$7,0) -> 20940 | E26: =IF(OR(E20=1,E22=1),'Rent Roll'!$F$6/BldgSF*ReimbPool/12*E$7,0) -> 20940 | F26: =IF(OR(F20=1,F22=1),'Rent Roll'!$F$6/BldgSF*ReimbPool/12*F$7,0) -> 20940 | G26: =IF(OR(G20=1,G22=1),'Rent Roll'!$F$6/BldgSF*ReimbPool/12*G$7,0) -> 20940 | H26: =IF(OR(H20=1,H22=1),'Rent Roll'!$F$6/BldgSF*ReimbPool/12*H$7,0) -> 20940 | I26: =IF(OR(I20=1,I22=1),'Rent Roll'!$F$6/BldgSF*ReimbPool/12*I$7,0) -> 21505.38 | J26: =IF(OR(J20=1,J22=1),'Rent Roll'!$F$6/BldgSF*ReimbPool/12*J$7,0) -> 21505.38 | K26: =IF(OR(K20=1,K22=1),'Rent Roll'!$F$6/BldgSF*ReimbPool/12*K$7,0) -> 21505.38 | ... BX26: =IF(OR(BX20=1,BX22=1),'Rent Roll'!$F$6/BldgSF*ReimbPool/12*BX$7,0) -> 24569.671
B27: TI (capital) | D27: =IF(D$4=EOMONTH(CloseDate,'Rent Roll'!$O$6+'Rent Roll'!$S$6),-'Rent Roll'!$F$6*'Rent Roll'!$T$6,0) -> 0 | E27: =IF(E$4=EOMONTH(CloseDate,'Rent Roll'!$O$6+'Rent Roll'!$S$6),-'Rent Roll'!$F$6*'Rent Roll'!$T$6,0) -> 0 | F27: =IF(F$4=EOMONTH(CloseDate,'Rent Roll'!$O$6+'Rent Roll'!$S$6),-'Rent Roll'!$F$6*'Rent Roll'!$T$6,0) -> 0 | G27: =IF(G$4=EOMONTH(CloseDate,'Rent Roll'!$O$6+'Rent Roll'!$S$6),-'Rent Roll'!$F$6*'Rent Roll'!$T$6,0) -> 0 | H27: =IF(H$4=EOMONTH(CloseDate,'Rent Roll'!$O$6+'Rent Roll'!$S$6),-'Rent Roll'!$F$6*'Rent Roll'!$T$6,0) -> 0 | I27: =IF(I$4=EOMONTH(CloseDate,'Rent Roll'!$O$6+'Rent Roll'!$S$6),-'Rent Roll'!$F$6*'Rent Roll'!$T$6,0) -> 0 | J27: =IF(J$4=EOMONTH(CloseDate,'Rent Roll'!$O$6+'Rent Roll'!$S$6),-'Rent Roll'!$F$6*'Rent Roll'!$T$6,0) -> 0 | K27: =IF(K$4=EOMONTH(CloseDate,'Rent Roll'!$O$6+'Rent Roll'!$S$6),-'Rent Roll'!$F$6*'Rent Roll'!$T$6,0) -> 0 | ... BX27: =IF(BX$4=EOMONTH(CloseDate,'Rent Roll'!$O$6+'Rent Roll'!$S$6),-'Rent Roll'!$F$6*'Rent Roll'!$T$6,0) -> 0
B28: LC (capital) | D28: =IF(D$4=EOMONTH(CloseDate,'Rent Roll'!$O$6+'Rent Roll'!$S$6),-'Rent Roll'!$U$6*'Rent Roll'!$F$6*'Rent Roll'!$X$6,0) -> 0 | E28: =IF(E$4=EOMONTH(CloseDate,'Rent Roll'!$O$6+'Rent Roll'!$S$6),-'Rent Roll'!$U$6*'Rent Roll'!$F$6*'Rent Roll'!$X$6,0) -> 0 | F28: =IF(F$4=EOMONTH(CloseDate,'Rent Roll'!$O$6+'Rent Roll'!$S$6),-'Rent Roll'!$U$6*'Rent Roll'!$F$6*'Rent Roll'!$X$6,0) -> 0 | G28: =IF(G$4=EOMONTH(CloseDate,'Rent Roll'!$O$6+'Rent Roll'!$S$6),-'Rent Roll'!$U$6*'Rent Roll'!$F$6*'Rent Roll'!$X$6,0) -> 0 | H28: =IF(H$4=EOMONTH(CloseDate,'Rent Roll'!$O$6+'Rent Roll'!$S$6),-'Rent Roll'!$U$6*'Rent Roll'!$F$6*'Rent Roll'!$X$6,0) -> 0 | I28: =IF(I$4=EOMONTH(CloseDate,'Rent Roll'!$O$6+'Rent Roll'!$S$6),-'Rent Roll'!$U$6*'Rent Roll'!$F$6*'Rent Roll'!$X$6,0) -> 0 | J28: =IF(J$4=EOMONTH(CloseDate,'Rent Roll'!$O$6+'Rent Roll'!$S$6),-'Rent Roll'!$U$6*'Rent Roll'!$F$6*'Rent Roll'!$X$6,0) -> 0 | K28: =IF(K$4=EOMONTH(CloseDate,'Rent Roll'!$O$6+'Rent Roll'!$S$6),-'Rent Roll'!$U$6*'Rent Roll'!$F$6*'Rent Roll'!$X$6,0) -> 0 | ... BX28: =IF(BX$4=EOMONTH(CloseDate,'Rent Roll'!$O$6+'Rent Roll'!$S$6),-'Rent Roll'!$U$6*'Rent Roll'!$F$6*'Rent Roll'!$X$6,0) -> 0
A29: ='Rent Roll'!C7 -> Carter & Associates Law | B29: =INDEX('Rent Roll'!$F$5:$F$46,MATCH('Rent Roll Calc'!A29,'Rent Roll'!$C$5:$C$46,0)) -> 12000
B30: Occupancy Flag | D30: =IF(AND('Rent Roll'!$N$7<>"Ghost",D$4<='Rent Roll'!$L$7),1,0) -> 1 | E30: =IF(AND('Rent Roll'!$N$7<>"Ghost",E$4<='Rent Roll'!$L$7),1,0) -> 1 | F30: =IF(AND('Rent Roll'!$N$7<>"Ghost",F$4<='Rent Roll'!$L$7),1,0) -> 1 | G30: =IF(AND('Rent Roll'!$N$7<>"Ghost",G$4<='Rent Roll'!$L$7),1,0) -> 1 | H30: =IF(AND('Rent Roll'!$N$7<>"Ghost",H$4<='Rent Roll'!$L$7),1,0) -> 1 | I30: =IF(AND('Rent Roll'!$N$7<>"Ghost",I$4<='Rent Roll'!$L$7),1,0) -> 1 | J30: =IF(AND('Rent Roll'!$N$7<>"Ghost",J$4<='Rent Roll'!$L$7),1,0) -> 1 | K30: =IF(AND('Rent Roll'!$N$7<>"Ghost",K$4<='Rent Roll'!$L$7),1,0) -> 1 | ... BX30: =IF(AND('Rent Roll'!$N$7<>"Ghost",BX$4<='Rent Roll'!$L$7),1,0) -> 0
B31: In-Place Rent | D31: =IF(D30=1,'Rent Roll'!$H$7/12*(1+'Rent Roll'!$I$7)^IF(D$4<'Rent Roll'!$Y$7,0,YEAR(D$4)-YEAR('Rent Roll'!$Y$7)+1),0) -> 22000 | E31: =IF(E30=1,'Rent Roll'!$H$7/12*(1+'Rent Roll'!$I$7)^IF(E$4<'Rent Roll'!$Y$7,0,YEAR(E$4)-YEAR('Rent Roll'!$Y$7)+1),0) -> 22000 | F31: =IF(F30=1,'Rent Roll'!$H$7/12*(1+'Rent Roll'!$I$7)^IF(F$4<'Rent Roll'!$Y$7,0,YEAR(F$4)-YEAR('Rent Roll'!$Y$7)+1),0) -> 22550 | G31: =IF(G30=1,'Rent Roll'!$H$7/12*(1+'Rent Roll'!$I$7)^IF(G$4<'Rent Roll'!$Y$7,0,YEAR(G$4)-YEAR('Rent Roll'!$Y$7)+1),0) -> 22550 | H31: =IF(H30=1,'Rent Roll'!$H$7/12*(1+'Rent Roll'!$I$7)^IF(H$4<'Rent Roll'!$Y$7,0,YEAR(H$4)-YEAR('Rent Roll'!$Y$7)+1),0) -> 22550 | I31: =IF(I30=1,'Rent Roll'!$H$7/12*(1+'Rent Roll'!$I$7)^IF(I$4<'Rent Roll'!$Y$7,0,YEAR(I$4)-YEAR('Rent Roll'!$Y$7)+1),0) -> 23113.75 | J31: =IF(J30=1,'Rent Roll'!$H$7/12*(1+'Rent Roll'!$I$7)^IF(J$4<'Rent Roll'!$Y$7,0,YEAR(J$4)-YEAR('Rent Roll'!$Y$7)+1),0) -> 23113.75 | K31: =IF(K30=1,'Rent Roll'!$H$7/12*(1+'Rent Roll'!$I$7)^IF(K$4<'Rent Roll'!$Y$7,0,YEAR(K$4)-YEAR('Rent Roll'!$Y$7)+1),0) -> 23113.75 | ... BX31: =IF(BX30=1,'Rent Roll'!$H$7/12*(1+'Rent Roll'!$I$7)^IF(BX$4<'Rent Roll'!$Y$7,0,YEAR(BX$4)-YEAR('Rent Roll'!$Y$7)+1),0) -> 0
B32: Re-Let Flag | D32: =IF(D$4>EOMONTH(CloseDate,'Rent Roll'!$O$7+'Rent Roll'!$S$7-1),1,0) -> 0 | E32: =IF(E$4>EOMONTH(CloseDate,'Rent Roll'!$O$7+'Rent Roll'!$S$7-1),1,0) -> 0 | F32: =IF(F$4>EOMONTH(CloseDate,'Rent Roll'!$O$7+'Rent Roll'!$S$7-1),1,0) -> 0 | G32: =IF(G$4>EOMONTH(CloseDate,'Rent Roll'!$O$7+'Rent Roll'!$S$7-1),1,0) -> 0 | H32: =IF(H$4>EOMONTH(CloseDate,'Rent Roll'!$O$7+'Rent Roll'!$S$7-1),1,0) -> 0 | I32: =IF(I$4>EOMONTH(CloseDate,'Rent Roll'!$O$7+'Rent Roll'!$S$7-1),1,0) -> 0 | J32: =IF(J$4>EOMONTH(CloseDate,'Rent Roll'!$O$7+'Rent Roll'!$S$7-1),1,0) -> 0 | K32: =IF(K$4>EOMONTH(CloseDate,'Rent Roll'!$O$7+'Rent Roll'!$S$7-1),1,0) -> 0 | ... BX32: =IF(BX$4>EOMONTH(CloseDate,'Rent Roll'!$O$7+'Rent Roll'!$S$7-1),1,0) -> 1
B33: Re-Let Rent (gross) | D33: =IF(D32=1,'Rent Roll'!$F$7*'Rent Roll'!$X$7/12*D$6,0) -> 0 | E33: =IF(E32=1,'Rent Roll'!$F$7*'Rent Roll'!$X$7/12*E$6,0) -> 0 | F33: =IF(F32=1,'Rent Roll'!$F$7*'Rent Roll'!$X$7/12*F$6,0) -> 0 | G33: =IF(G32=1,'Rent Roll'!$F$7*'Rent Roll'!$X$7/12*G$6,0) -> 0 | H33: =IF(H32=1,'Rent Roll'!$F$7*'Rent Roll'!$X$7/12*H$6,0) -> 0 | I33: =IF(I32=1,'Rent Roll'!$F$7*'Rent Roll'!$X$7/12*I$6,0) -> 0 | J33: =IF(J32=1,'Rent Roll'!$F$7*'Rent Roll'!$X$7/12*J$6,0) -> 0 | K33: =IF(K32=1,'Rent Roll'!$F$7*'Rent Roll'!$X$7/12*K$6,0) -> 0 | ... BX33: =IF(BX32=1,'Rent Roll'!$F$7*'Rent Roll'!$X$7/12*BX$6,0) -> 28947.684
B34: Free Rent Adj | D34: =IF(AND(D$4>EOMONTH(CloseDate,'Rent Roll'!$O$7+'Rent Roll'!$S$7-1),D$4<=EOMONTH(CloseDate,'Rent Roll'!$O$7+'Rent Roll'!$S$7-1+'Rent Roll'!$V$7)),-D33,0) -> 0 | E34: =IF(AND(E$4>EOMONTH(CloseDate,'Rent Roll'!$O$7+'Rent Roll'!$S$7-1),E$4<=EOMONTH(CloseDate,'Rent Roll'!$O$7+'Rent Roll'!$S$7-1+'Rent Roll'!$V$7)),-E33,0) -> 0 | F34: =IF(AND(F$4>EOMONTH(CloseDate,'Rent Roll'!$O$7+'Rent Roll'!$S$7-1),F$4<=EOMONTH(CloseDate,'Rent Roll'!$O$7+'Rent Roll'!$S$7-1+'Rent Roll'!$V$7)),-F33,0) -> 0 | G34: =IF(AND(G$4>EOMONTH(CloseDate,'Rent Roll'!$O$7+'Rent Roll'!$S$7-1),G$4<=EOMONTH(CloseDate,'Rent Roll'!$O$7+'Rent Roll'!$S$7-1+'Rent Roll'!$V$7)),-G33,0) -> 0 | H34: =IF(AND(H$4>EOMONTH(CloseDate,'Rent Roll'!$O$7+'Rent Roll'!$S$7-1),H$4<=EOMONTH(CloseDate,'Rent Roll'!$O$7+'Rent Roll'!$S$7-1+'Rent Roll'!$V$7)),-H33,0) -> 0 | I34: =IF(AND(I$4>EOMONTH(CloseDate,'Rent Roll'!$O$7+'Rent Roll'!$S$7-1),I$4<=EOMONTH(CloseDate,'Rent Roll'!$O$7+'Rent Roll'!$S$7-1+'Rent Roll'!$V$7)),-I33,0) -> 0 | J34: =IF(AND(J$4>EOMONTH(CloseDate,'Rent Roll'!$O$7+'Rent Roll'!$S$7-1),J$4<=EOMONTH(CloseDate,'Rent Roll'!$O$7+'Rent Roll'!$S$7-1+'Rent Roll'!$V$7)),-J33,0) -> 0 | K34: =IF(AND(K$4>EOMONTH(CloseDate,'Rent Roll'!$O$7+'Rent Roll'!$S$7-1),K$4<=EOMONTH(CloseDate,'Rent Roll'!$O$7+'Rent Roll'!$S$7-1+'Rent Roll'!$V$7)),-K33,0) -> 0 | ... BX34: =IF(AND(BX$4>EOMONTH(CloseDate,'Rent Roll'!$O$7+'Rent Roll'!$S$7-1),BX$4<=EOMONTH(CloseDate,'Rent Roll'!$O$7+'Rent Roll'!$S$7-1+'Rent Roll'!$V$7)),-BX33,0) -> 0
B35: Net Base Rent | D35: =D31+D33+D34 -> 22000 | E35: =E31+E33+E34 -> 22000 | F35: =F31+F33+F34 -> 22550 | G35: =G31+G33+G34 -> 22550 | H35: =H31+H33+H34 -> 22550 | I35: =I31+I33+I34 -> 23113.75 | J35: =J31+J33+J34 -> 23113.75 | K35: =K31+K33+K34 -> 23113.75 | ... BX35: =BX31+BX33+BX34 -> 28947.684
B36: Opex Recovery (NNN) | D36: =IF(OR(D30=1,D32=1),'Rent Roll'!$F$7/BldgSF*ReimbPool/12*D$7,0) -> 10470 | E36: =IF(OR(E30=1,E32=1),'Rent Roll'!$F$7/BldgSF*ReimbPool/12*E$7,0) -> 10470 | F36: =IF(OR(F30=1,F32=1),'Rent Roll'!$F$7/BldgSF*ReimbPool/12*F$7,0) -> 10470 | G36: =IF(OR(G30=1,G32=1),'Rent Roll'!$F$7/BldgSF*ReimbPool/12*G$7,0) -> 10470 | H36: =IF(OR(H30=1,H32=1),'Rent Roll'!$F$7/BldgSF*ReimbPool/12*H$7,0) -> 10470 | I36: =IF(OR(I30=1,I32=1),'Rent Roll'!$F$7/BldgSF*ReimbPool/12*I$7,0) -> 10752.69 | J36: =IF(OR(J30=1,J32=1),'Rent Roll'!$F$7/BldgSF*ReimbPool/12*J$7,0) -> 10752.69 | K36: =IF(OR(K30=1,K32=1),'Rent Roll'!$F$7/BldgSF*ReimbPool/12*K$7,0) -> 10752.69 | ... BX36: =IF(OR(BX30=1,BX32=1),'Rent Roll'!$F$7/BldgSF*ReimbPool/12*BX$7,0) -> 12284.835
B37: TI (capital) | D37: =IF(D$4=EOMONTH(CloseDate,'Rent Roll'!$O$7+'Rent Roll'!$S$7),-'Rent Roll'!$F$7*'Rent Roll'!$T$7,0) -> 0 | E37: =IF(E$4=EOMONTH(CloseDate,'Rent Roll'!$O$7+'Rent Roll'!$S$7),-'Rent Roll'!$F$7*'Rent Roll'!$T$7,0) -> 0 | F37: =IF(F$4=EOMONTH(CloseDate,'Rent Roll'!$O$7+'Rent Roll'!$S$7),-'Rent Roll'!$F$7*'Rent Roll'!$T$7,0) -> 0 | G37: =IF(G$4=EOMONTH(CloseDate,'Rent Roll'!$O$7+'Rent Roll'!$S$7),-'Rent Roll'!$F$7*'Rent Roll'!$T$7,0) -> 0 | H37: =IF(H$4=EOMONTH(CloseDate,'Rent Roll'!$O$7+'Rent Roll'!$S$7),-'Rent Roll'!$F$7*'Rent Roll'!$T$7,0) -> 0 | I37: =IF(I$4=EOMONTH(CloseDate,'Rent Roll'!$O$7+'Rent Roll'!$S$7),-'Rent Roll'!$F$7*'Rent Roll'!$T$7,0) -> 0 | J37: =IF(J$4=EOMONTH(CloseDate,'Rent Roll'!$O$7+'Rent Roll'!$S$7),-'Rent Roll'!$F$7*'Rent Roll'!$T$7,0) -> 0 | K37: =IF(K$4=EOMONTH(CloseDate,'Rent Roll'!$O$7+'Rent Roll'!$S$7),-'Rent Roll'!$F$7*'Rent Roll'!$T$7,0) -> 0 | ... BX37: =IF(BX$4=EOMONTH(CloseDate,'Rent Roll'!$O$7+'Rent Roll'!$S$7),-'Rent Roll'!$F$7*'Rent Roll'!$T$7,0) -> 0
B38: LC (capital) | D38: =IF(D$4=EOMONTH(CloseDate,'Rent Roll'!$O$7+'Rent Roll'!$S$7),-'Rent Roll'!$U$7*'Rent Roll'!$F$7*'Rent Roll'!$X$7,0) -> 0 | E38: =IF(E$4=EOMONTH(CloseDate,'Rent Roll'!$O$7+'Rent Roll'!$S$7),-'Rent Roll'!$U$7*'Rent Roll'!$F$7*'Rent Roll'!$X$7,0) -> 0 | F38: =IF(F$4=EOMONTH(CloseDate,'Rent Roll'!$O$7+'Rent Roll'!$S$7),-'Rent Roll'!$U$7*'Rent Roll'!$F$7*'Rent Roll'!$X$7,0) -> 0 | G38: =IF(G$4=EOMONTH(CloseDate,'Rent Roll'!$O$7+'Rent Roll'!$S$7),-'Rent Roll'!$U$7*'Rent Roll'!$F$7*'Rent Roll'!$X$7,0) -> 0 | H38: =IF(H$4=EOMONTH(CloseDate,'Rent Roll'!$O$7+'Rent Roll'!$S$7),-'Rent Roll'!$U$7*'Rent Roll'!$F$7*'Rent Roll'!$X$7,0) -> 0 | I38: =IF(I$4=EOMONTH(CloseDate,'Rent Roll'!$O$7+'Rent Roll'!$S$7),-'Rent Roll'!$U$7*'Rent Roll'!$F$7*'Rent Roll'!$X$7,0) -> 0 | J38: =IF(J$4=EOMONTH(CloseDate,'Rent Roll'!$O$7+'Rent Roll'!$S$7),-'Rent Roll'!$U$7*'Rent Roll'!$F$7*'Rent Roll'!$X$7,0) -> 0 | K38: =IF(K$4=EOMONTH(CloseDate,'Rent Roll'!$O$7+'Rent Roll'!$S$7),-'Rent Roll'!$U$7*'Rent Roll'!$F$7*'Rent Roll'!$X$7,0) -> 0 | ... BX38: =IF(BX$4=EOMONTH(CloseDate,'Rent Roll'!$O$7+'Rent Roll'!$S$7),-'Rent Roll'!$U$7*'Rent Roll'!$F$7*'Rent Roll'!$X$7,0) -> 0
A39: ='Rent Roll'!C8 -> Pinnacle Wealth Advisors | B39: =INDEX('Rent Roll'!$F$5:$F$46,MATCH('Rent Roll Calc'!A39,'Rent Roll'!$C$5:$C$46,0)) -> 11000
B40: Occupancy Flag | D40: =IF(AND('Rent Roll'!$N$8<>"Ghost",D$4<='Rent Roll'!$L$8),1,0) -> 1 | E40: =IF(AND('Rent Roll'!$N$8<>"Ghost",E$4<='Rent Roll'!$L$8),1,0) -> 1 | F40: =IF(AND('Rent Roll'!$N$8<>"Ghost",F$4<='Rent Roll'!$L$8),1,0) -> 1 | G40: =IF(AND('Rent Roll'!$N$8<>"Ghost",G$4<='Rent Roll'!$L$8),1,0) -> 1 | H40: =IF(AND('Rent Roll'!$N$8<>"Ghost",H$4<='Rent Roll'!$L$8),1,0) -> 1 | I40: =IF(AND('Rent Roll'!$N$8<>"Ghost",I$4<='Rent Roll'!$L$8),1,0) -> 1 | J40: =IF(AND('Rent Roll'!$N$8<>"Ghost",J$4<='Rent Roll'!$L$8),1,0) -> 1 | K40: =IF(AND('Rent Roll'!$N$8<>"Ghost",K$4<='Rent Roll'!$L$8),1,0) -> 1 | ... BX40: =IF(AND('Rent Roll'!$N$8<>"Ghost",BX$4<='Rent Roll'!$L$8),1,0) -> 0
B41: In-Place Rent | D41: =IF(D40=1,'Rent Roll'!$H$8/12*(1+'Rent Roll'!$I$8)^IF(D$4<'Rent Roll'!$Y$8,0,YEAR(D$4)-YEAR('Rent Roll'!$Y$8)+1),0) -> 18562.5 | E41: =IF(E40=1,'Rent Roll'!$H$8/12*(1+'Rent Roll'!$I$8)^IF(E$4<'Rent Roll'!$Y$8,0,YEAR(E$4)-YEAR('Rent Roll'!$Y$8)+1),0) -> 18562.5 | F41: =IF(F40=1,'Rent Roll'!$H$8/12*(1+'Rent Roll'!$I$8)^IF(F$4<'Rent Roll'!$Y$8,0,YEAR(F$4)-YEAR('Rent Roll'!$Y$8)+1),0) -> 18562.5 | G41: =IF(G40=1,'Rent Roll'!$H$8/12*(1+'Rent Roll'!$I$8)^IF(G$4<'Rent Roll'!$Y$8,0,YEAR(G$4)-YEAR('Rent Roll'!$Y$8)+1),0) -> 18562.5 | H41: =IF(H40=1,'Rent Roll'!$H$8/12*(1+'Rent Roll'!$I$8)^IF(H$4<'Rent Roll'!$Y$8,0,YEAR(H$4)-YEAR('Rent Roll'!$Y$8)+1),0) -> 18562.5 | I41: =IF(I40=1,'Rent Roll'!$H$8/12*(1+'Rent Roll'!$I$8)^IF(I$4<'Rent Roll'!$Y$8,0,YEAR(I$4)-YEAR('Rent Roll'!$Y$8)+1),0) -> 18933.75 | J41: =IF(J40=1,'Rent Roll'!$H$8/12*(1+'Rent Roll'!$I$8)^IF(J$4<'Rent Roll'!$Y$8,0,YEAR(J$4)-YEAR('Rent Roll'!$Y$8)+1),0) -> 18933.75 | K41: =IF(K40=1,'Rent Roll'!$H$8/12*(1+'Rent Roll'!$I$8)^IF(K$4<'Rent Roll'!$Y$8,0,YEAR(K$4)-YEAR('Rent Roll'!$Y$8)+1),0) -> 18933.75 | ... BX41: =IF(BX40=1,'Rent Roll'!$H$8/12*(1+'Rent Roll'!$I$8)^IF(BX$4<'Rent Roll'!$Y$8,0,YEAR(BX$4)-YEAR('Rent Roll'!$Y$8)+1),0) -> 0
B42: Re-Let Flag | D42: =IF(D$4>EOMONTH(CloseDate,'Rent Roll'!$O$8+'Rent Roll'!$S$8-1),1,0) -> 0 | E42: =IF(E$4>EOMONTH(CloseDate,'Rent Roll'!$O$8+'Rent Roll'!$S$8-1),1,0) -> 0 | F42: =IF(F$4>EOMONTH(CloseDate,'Rent Roll'!$O$8+'Rent Roll'!$S$8-1),1,0) -> 0 | G42: =IF(G$4>EOMONTH(CloseDate,'Rent Roll'!$O$8+'Rent Roll'!$S$8-1),1,0) -> 0 | H42: =IF(H$4>EOMONTH(CloseDate,'Rent Roll'!$O$8+'Rent Roll'!$S$8-1),1,0) -> 0 | I42: =IF(I$4>EOMONTH(CloseDate,'Rent Roll'!$O$8+'Rent Roll'!$S$8-1),1,0) -> 0 | J42: =IF(J$4>EOMONTH(CloseDate,'Rent Roll'!$O$8+'Rent Roll'!$S$8-1),1,0) -> 0 | K42: =IF(K$4>EOMONTH(CloseDate,'Rent Roll'!$O$8+'Rent Roll'!$S$8-1),1,0) -> 0 | ... BX42: =IF(BX$4>EOMONTH(CloseDate,'Rent Roll'!$O$8+'Rent Roll'!$S$8-1),1,0) -> 1
...

Sheet IC Summary
A1: INVESTMENT COMMITTEE SUMMARY
A3: DEAL OVERVIEW
A4: Property Name | D4: =Assumptions!A1 -> SouthPark Centre
A5: Address | D5: =Assumptions!A2 -> 4800 Sharon Road, Charlotte, NC 2821
A6: Submarket | D6: ='Rental Comp Analysis'!C3 -> SouthPark
A7: Total SF | D7: =BldgSF -> 280000
A8: Stories | D8: 8 | E8: from OM
A9: Year Built | D9: 2014 | E9: from OM
A10: Purchase Price | D10: =PurchasePrice -> 50000000
A11: Price / SF | D11: =D10/D7 -> 178.57143
A12: Going-In Cap Rate (Reconciled) | D12: ='Sales Comp Analysis'!I29 -> 0.05743247
A13: Physical Occupancy (Corrected) | D13: ='Property Cash Flow'!L6 -> 0.77357143
A14: Number of Tenants (Actual) | D14: =COUNTIF('Rent Roll'!N5:N32,"Occupied") -> 18
A15: WALT (Years) | D15: =('Rent Roll'!L34-CloseDate)/365.4 -> 1.8160562
A16: Largest Tenant | D16: ='Rent Roll'!C5 -> Meridian Financial Group
A17: Near-Term Rollover Exposure (SF) | D17: ='Rent Roll'!F5 -> 76000
A19: MARKET CONTEXT
A20: Submarket Vacancy | D20: ='SouthPark Submarket'!B11 -> 14.8%
A21: Class B+ Asking Rent (NNN) | D21: ='SouthPark Submarket'!B20 -> $24.00 - $27.00/SF
A22: 12-Month Rent Growth | D22: =+'SouthPark Submarket'!B40 -> 2.8%
A23: TTM Net Absorption | D23: =+'SouthPark Submarket'!B27 -> 185,000 SF
A24: Supply Pipeline | D24: ='SouthPark Submarket'!B33 -> 320,000 SF
A26: TENANCY SUMMARY
A27: WALT | D27: =D15 -> 1.8160562
A28: Top 5 Tenant Concentration (% of SF) | D28: =SUMIFS('Rent Roll'!$F$5:$F$32,'Rent Roll'!$A$5:$A$32,"<=5")/D7 -> 0.47678571
A29: Near-Term Rollover (SF / % of Bldg) | D29: =D17 -> 76000
A30: Avg Mark-to-Market Spread | D30: ='Rent Roll'!X34-'Rent Roll'!G34 -> 8.773008 | E30: incl. vacancy
A31: Weighted Avg In-Place Rent | D31: ='Rent Roll'!G34 -> 15.903036
A33: FINANCIAL SUMMARY
A34: Broker's Stated NOI | D34: 3880000
A35: Reconciled NOI | D35: ='Property Cash Flow'!M19*12 -> 3761085.4
A36: Year 1 Proforma NOI | D36: ='Property Cash Flow'!E19 -> 2957772.2
A37: Stabilized NOI | D37: ='Property Cash Flow'!H19 -> 6027050.5
A38: Exit Year NOI | D38: ='Exit Analysis'!B5 -> 6545315.3
A39: Unlevered IRR | D39: ='Property Cash Flow'!B35 -> 0.11468807
A41: DEBT TERMS
A42: Selected Lender | D42: ='Leverage Options'!B4 -> First Southeast Bank
A43: Loan Type | D43: ='Leverage Options'!B5 -> Construction-to-Permanent
A44: Rate | D44: ='Leverage Options'!B9 -> 7.10%
A45: Loan Amount | D45: =MAX('Leverage Options'!B26,MIN('Leverage Options'!B27:B28)) -> 57936597
...

Sheet LOI
A1: LETTER OF INTENT
A3: HARBORVIEW CAPITAL PARTNERS
A5: PROPERTY DETAILS
A6: Property Name: | B6: =Assumptions!A1 -> SouthPark Centre
A7: Address: | B7: =Assumptions!A2 -> 4800 Sharon Road, Charlotte, NC 2821
A8: Total SF: | B8: =BldgSF -> 280000
A10: TRANSACTION TERMS
A11: Buyer: | B11: =A3 -> HARBORVIEW CAPITAL PARTNERS | C11: e.g. Harborview Capital Partners or its designee
A12: Purchase Price: | B12: =PurchasePrice -> 50000000 | C12: Link to model
A13: Deposit: | B13: =B12*1% -> 500000 | C13: Typically 1% of purchase price | D13: From email 4
A14: Due Diligence Period: | B14: 45 | C14: Calendar days from execution | D14: From email 4
A15: Financing Contingency: | B15: 30 | C15: Calendar days from DD expiration | D15: From email 4
A16: Target Close Date: | B16: =CloseDate -> 46265
A18: CONDITIONS
A19: Access: | B19: Full access to property and all books/records during DD | C19: Property access during DD period | D19: From email 4
A20: Exclusivity: | B20: 60 days | C20: Period of exclusivity from execution | D20: From email 4
A21: Existing Contracts: | B21: Assignable at close, subject to review during diligence | C21: Assignment of service contracts | D21: From email 4
A22: Tenant Estoppels: | B22: At least 75% of tenants by occupied SF | C22: Required from what % of tenants | D22: From email 4
A23: Title & Survey: | B23: Standard title commitment and ALTA survey | C23: Clean title, ALTA survey | D23: From email 4
A24: Environmental: | B24: Phase I at seller's cost, Phase II if flagged | C24: Phase I/II requirements | D24: From email 4
A26: EXPIRATION
A27: This LOI expires: | B27: 10 | C27: Business days from date of issuance | D27: From email 4

Sheet Property Cash Flow
A1: SouthPark Centre — Cash Flow Summary
A2: in $'000s
A3: Year # | D3: 0 | E3: =D3+1 -> 1 | F3: =E3+1 -> 2 | G3: =F3+1 -> 3 | H3: =G3+1 -> 4 | I3: =H3+1 -> 5 | J3: =I3+1 -> 6 | L3: =INT((L4-1)/12)+1 -> 0 | M3: =INT((M4-1)/12)+1 -> 1 | N3: =INT((N4-1)/12)+1 -> 1 | O3: =INT((O4-1)/12)+1 -> 1 | P3: =INT((P4-1)/12)+1 -> 1 | Q3: =INT((Q4-1)/12)+1 -> 1 | R3: =INT((R4-1)/12)+1 -> 1 | S3: =INT((S4-1)/12)+1 -> 1 | ... CF3: =INT((CF4-1)/12)+1 -> 6
A4: Month # | D4: 0 | E4: =D4+12 -> 12 | F4: =E4+12 -> 24 | G4: =F4+12 -> 36 | H4: =G4+12 -> 48 | I4: =H4+12 -> 60 | J4: =I4+12 -> 72 | L4: ='Rent Roll Calc'!D3 -> 0 | M4: ='Rent Roll Calc'!E3 -> 1 | N4: ='Rent Roll Calc'!F3 -> 2 | O4: ='Rent Roll Calc'!G3 -> 3 | P4: ='Rent Roll Calc'!H3 -> 4 | Q4: ='Rent Roll Calc'!I3 -> 5 | R4: ='Rent Roll Calc'!J3 -> 6 | S4: ='Rent Roll Calc'!K3 -> 7 | ... CF4: ='Rent Roll Calc'!BX3 -> 72
A5: Period End | D5: =+EOMONTH(CloseDate,0) -> 46265 | E5: =EOMONTH(D5,12) -> 46630 | F5: =EOMONTH(E5,12) -> 46996 | G5: =EOMONTH(F5,12) -> 47361 | H5: =EOMONTH(G5,12) -> 47726 | I5: =EOMONTH(H5,12) -> 48091 | J5: =EOMONTH(I5,12) -> 48457 | L5: ='Rent Roll Calc'!D4 -> 46265 | M5: ='Rent Roll Calc'!E4 -> 46295 | N5: ='Rent Roll Calc'!F4 -> 46326 | O5: ='Rent Roll Calc'!G4 -> 46356 | P5: ='Rent Roll Calc'!H4 -> 46387 | Q5: ='Rent Roll Calc'!I4 -> 46418 | R5: ='Rent Roll Calc'!J4 -> 46446 | S5: ='Rent Roll Calc'!K4 -> 46477 | ... CF5: ='Rent Roll Calc'!BX4 -> 48457
A6: Occupancy % | D6: =AVERAGEIFS($L6:$CF6,$L$3:$CF$3,D$3) -> 0.77357143 | E6: =AVERAGEIFS($L6:$CF6,$L$3:$CF$3,E$3) -> 0.68791667 | F6: =AVERAGEIFS($L6:$CF6,$L$3:$CF$3,F$3) -> 0.94074405 | G6: =AVERAGEIFS($L6:$CF6,$L$3:$CF$3,G$3) -> 0.90452381 | H6: =AVERAGEIFS($L6:$CF6,$L$3:$CF$3,H$3) -> 0.96104167 | I6: =AVERAGEIFS($L6:$CF6,$L$3:$CF$3,I$3) -> 0.97738095 | J6: =AVERAGEIFS($L6:$CF6,$L$3:$CF$3,J$3) -> 0.97818452 | L6: ='Rent Roll Calc'!D359/BldgSF -> 0.77357143 | M6: ='Rent Roll Calc'!E359/BldgSF -> 0.77357143 | N6: ='Rent Roll Calc'!F359/BldgSF -> 0.80392857 | O6: ='Rent Roll Calc'!G359/BldgSF -> 0.55535714 | P6: ='Rent Roll Calc'!H359/BldgSF -> 0.57607143 | Q6: ='Rent Roll Calc'!I359/BldgSF -> 0.60892857 | R6: ='Rent Roll Calc'!J359/BldgSF -> 0.63571429 | S6: ='Rent Roll Calc'!K359/BldgSF -> 0.63571429 | ... CF6: ='Rent Roll Calc'!BX359/BldgSF -> 0.99357143
A8: Gross Rental Income | D8: =SUMIFS($L8:$CF8,$L$3:$CF$3,D$3) -> 0 | E8: =SUMIFS($L8:$CF8,$L$3:$CF$3,E$3) -> 4242046.3 | F8: =SUMIFS($L8:$CF8,$L$3:$CF$3,F$3) -> 6442836.2 | G8: =SUMIFS($L8:$CF8,$L$3:$CF$3,G$3) -> 6521652.5 | H8: =SUMIFS($L8:$CF8,$L$3:$CF$3,H$3) -> 7297171.5 | I8: =SUMIFS($L8:$CF8,$L$3:$CF$3,I$3) -> 7679584.1 | J8: =SUMIFS($L8:$CF8,$L$3:$CF$3,J$3) -> 7953389.9 | M8: ='Rent Roll Calc'!E352+'Rent Roll Calc'!E353 -> 368853.75 | N8: ='Rent Roll Calc'!F352+'Rent Roll Calc'!F353 -> 386879.22 | O8: ='Rent Roll Calc'!G352+'Rent Roll Calc'!G353 -> 276827.47 | P8: ='Rent Roll Calc'!H352+'Rent Roll Calc'!H353 -> 289186.84 | Q8: ='Rent Roll Calc'!I352+'Rent Roll Calc'!I353 -> 312147.59 | R8: ='Rent Roll Calc'!J352+'Rent Roll Calc'!J353 -> 328333.19 | S8: ='Rent Roll Calc'!K352+'Rent Roll Calc'!K353 -> 328751.78 | T8: ='Rent Roll Calc'!L352+'Rent Roll Calc'!L353 -> 348769.52 | ... CF8: ='Rent Roll Calc'!BX352+'Rent Roll Calc'!BX353 -> 678889.91
A9: Free Rent | D9: =SUMIFS($L9:$CF9,$L$3:$CF$3,D$3) -> 0 | E9: =SUMIFS($L9:$CF9,$L$3:$CF$3,E$3) -> -378313.2 | F9: =SUMIFS($L9:$CF9,$L$3:$CF$3,F$3) -> -332829.86 | G9: =SUMIFS($L9:$CF9,$L$3:$CF$3,G$3) -> -214452.09 | H9: =SUMIFS($L9:$CF9,$L$3:$CF$3,H$3) -> -156624.11 | I9: =SUMIFS($L9:$CF9,$L$3:$CF$3,I$3) -> -76390.288 | J9: =SUMIFS($L9:$CF9,$L$3:$CF$3,J$3) -> -65277.575 | M9: ='Rent Roll Calc'!E354 -> 0 | N9: ='Rent Roll Calc'!F354 -> -17475.469 | O9: ='Rent Roll Calc'!G354 -> -30633.469 | P9: ='Rent Roll Calc'!H354 -> -25082.437 | Q9: ='Rent Roll Calc'!I354 -> -31671.717 | R9: ='Rent Roll Calc'!J354 -> -35261.178 | S9: ='Rent Roll Calc'!K354 -> -15835.859 | T9: ='Rent Roll Calc'!L354 -> -18580.741 | ... CF9: ='Rent Roll Calc'!BX354 -> 0
A10: Net Rental Income | D10: =SUMIFS($L10:$CF10,$L$3:$CF$3,D$3) -> 0 | E10: =SUMIFS($L10:$CF10,$L$3:$CF$3,E$3) -> 3863733.1 | F10: =SUMIFS($L10:$CF10,$L$3:$CF$3,F$3) -> 6110006.3 | G10: =SUMIFS($L10:$CF10,$L$3:$CF$3,G$3) -> 6307200.4 | H10: =SUMIFS($L10:$CF10,$L$3:$CF$3,H$3) -> 7140547.3 | I10: =SUMIFS($L10:$CF10,$L$3:$CF$3,I$3) -> 7603193.8 | J10: =SUMIFS($L10:$CF10,$L$3:$CF$3,J$3) -> 7888112.4 | M10: =SUM(M8:M9) -> 368853.75 | N10: =SUM(N8:N9) -> 369403.75 | O10: =SUM(O8:O9) -> 246194 | P10: =SUM(P8:P9) -> 264104.41 | Q10: =SUM(Q8:Q9) -> 280475.87 | R10: =SUM(R8:R9) -> 293072.01 | S10: =SUM(S8:S9) -> 312915.92 | T10: =SUM(T8:T9) -> 330188.78 | ... CF10: =SUM(CF8:CF9) -> 678889.91
A12: Expense Recovery (NNN) | D12: =SUMIFS($L12:$CF12,$L$3:$CF$3,D$3) -> 0 | E12: =SUMIFS($L12:$CF12,$L$3:$CF$3,E$3) -> 2053278.9 | F12: =SUMIFS($L12:$CF12,$L$3:$CF$3,F$3) -> 2884395.7 | G12: =SUMIFS($L12:$CF12,$L$3:$CF$3,G$3) -> 2845516.7 | H12: =SUMIFS($L12:$CF12,$L$3:$CF$3,H$3) -> 3106601.8 | I12: =SUMIFS($L12:$CF12,$L$3:$CF$3,I$3) -> 3245276.3 | J12: =SUMIFS($L12:$CF12,$L$3:$CF$3,J$3) -> 3335899.7 | M12: ='Rent Roll Calc'!E356 -> 188983.5 | N12: ='Rent Roll Calc'!F356 -> 196399.75 | O12: ='Rent Roll Calc'!G356 -> 135673.75 | P12: ='Rent Roll Calc'!H356 -> 140734.25 | Q12: ='Rent Roll Calc'!I356 -> 152777.8 | R12: ='Rent Roll Calc'!J356 -> 159498.23 | S12: ='Rent Roll Calc'!K356 -> 159498.23 | T12: ='Rent Roll Calc'!L356 -> 167383.54 | ... CF12: ='Rent Roll Calc'!BX356 -> 284803.43
A13: Other Income | D13: =SUMIFS($L13:$CF13,$L$3:$CF$3,D$3) -> 0 | E13: =SUMIFS($L13:$CF13,$L$3:$CF$3,E$3) -> 282000 | F13: =SUMIFS($L13:$CF13,$L$3:$CF$3,F$3) -> 288390 | G13: =SUMIFS($L13:$CF13,$L$3:$CF$3,G$3) -> 294936.55 | H13: =SUMIFS($L13:$CF13,$L$3:$CF$3,H$3) -> 301643.5 | I13: =SUMIFS($L13:$CF13,$L$3:$CF$3,I$3) -> 308514.79 | J13: =SUMIFS($L13:$CF13,$L$3:$CF$3,J$3) -> 315554.47 | M13: =(Assumptions!$B$45*(1+ParkGrowth)^('Rent Roll Calc'!E$5-1)+Assumptions!$B$46*(1+AntennaGrowth)^('Rent Roll Calc'!E$5-1)+Assumptions!$B$47)/12 -> 23500 | N13: =(Assumptions!$B$45*(1+ParkGrowth)^('Rent Roll Calc'!F$5-1)+Assumptions!$B$46*(1+AntennaGrowth)^('Rent Roll Calc'!F$5-1)+Assumptions!$B$47)/12 -> 23500 | O13: =(Assumptions!$B$45*(1+ParkGrowth)^('Rent Roll Calc'!G$5-1)+Assumptions!$B$46*(1+AntennaGrowth)^('Rent Roll Calc'!G$5-1)+Assumptions!$B$47)/12 -> 23500 | P13: =(Assumptions!$B$45*(1+ParkGrowth)^('Rent Roll Calc'!H$5-1)+Assumptions!$B$46*(1+AntennaGrowth)^('Rent Roll Calc'!H$5-1)+Assumptions!$B$47)/12 -> 23500 | Q13: =(Assumptions!$B$45*(1+ParkGrowth)^('Rent Roll Calc'!I$5-1)+Assumptions!$B$46*(1+AntennaGrowth)^('Rent Roll Calc'!I$5-1)+Assumptions!$B$47)/12 -> 23500 | R13: =(Assumptions!$B$45*(1+ParkGrowth)^('Rent Roll Calc'!J$5-1)+Assumptions!$B$46*(1+AntennaGrowth)^('Rent Roll Calc'!J$5-1)+Assumptions!$B$47)/12 -> 23500 | S13: =(Assumptions!$B$45*(1+ParkGrowth)^('Rent Roll Calc'!K$5-1)+Assumptions!$B$46*(1+AntennaGrowth)^('Rent Roll Calc'!K$5-1)+Assumptions!$B$47)/12 -> 23500 | T13: =(Assumptions!$B$45*(1+ParkGrowth)^('Rent Roll Calc'!L$5-1)+Assumptions!$B$46*(1+AntennaGrowth)^('Rent Roll Calc'!L$5-1)+Assumptions!$B$47)/12 -> 23500 | ... CF13: =(Assumptions!$B$45*(1+ParkGrowth)^('Rent Roll Calc'!BX$5-1)+Assumptions!$B$46*(1+AntennaGrowth)^('Rent Roll Calc'!BX$5-1)+Assumptions!$B$47)/12 -> 26296.206
A14: Effective Gross Income | D14: =D10+D12+D13 -> 0 | E14: =E10+E12+E13 -> 6199012 | F14: =F10+F12+F13 -> 9282792.1 | G14: =G10+G12+G13 -> 9447653.7 | H14: =H10+H12+H13 -> 10548793 | I14: =I10+I12+I13 -> 11156985 | J14: =J10+J12+J13 -> 11539567 | M14: =M10+M12+M13 -> 581337.25 | N14: =N10+N12+N13 -> 589303.5 | O14: =O10+O12+O13 -> 405367.75 | P14: =P10+P12+P13 -> 428338.66 | Q14: =Q10+Q12+Q13 -> 456753.68 | R14: =R10+R12+R13 -> 476070.24 | S14: =S10+S12+S13 -> 495914.16 | T14: =T10+T12+T13 -> 521072.32 | ... CF14: =CF10+CF12+CF13 -> 989989.55
A16: General Vacancy Adjustment | D16: =SUMIFS($L16:$CF16,$L$3:$CF$3,D$3) -> 0 | E16: =SUMIFS($L16:$CF16,$L$3:$CF$3,E$3) -> 0 | F16: =SUMIFS($L16:$CF16,$L$3:$CF$3,F$3) -> -633124.25 | G16: =SUMIFS($L16:$CF16,$L$3:$CF$3,G$3) -> -364160.33 | H16: =SUMIFS($L16:$CF16,$L$3:$CF$3,H$3) -> -876620.16 | I16: =SUMIFS($L16:$CF16,$L$3:$CF$3,I$3) -> -1089696.2 | J16: =SUMIFS($L16:$CF16,$L$3:$CF$3,J$3) -> -1135164.7 | M16: =(SUM(M8,M12)/M6)*-(MAX('Property Cash Flow'!M6-Assumptions!$B$22,0)) -> 0 | N16: =(SUM(N8,N12)/N6)*-(MAX('Property Cash Flow'!N6-Assumptions!$B$22,0)) -> 0 | O16: =(SUM(O8,O12)/O6)*-(MAX('Property Cash Flow'!O6-Assumptions!$B$22,0)) -> 0 | P16: =(SUM(P8,P12)/P6)*-(MAX('Property Cash Flow'!P6-Assumptions!$B$22,0)) -> 0 | Q16: =(SUM(Q8,Q12)/Q6)*-(MAX('Property Cash Flow'!Q6-Assumptions!$B$22,0)) -> 0 | R16: =(SUM(R8,R12)/R6)*-(MAX('Property Cash Flow'!R6-Assumptions!$B$22,0)) -> 0 | S16: =(SUM(S8,S12)/S6)*-(MAX('Property Cash Flow'!S6-Assumptions!$B$22,0)) -> 0 | T16: =(SUM(T8,T12)/T6)*-(MAX('Property Cash Flow'!T6-Assumptions!$B$22,0)) -> 0 | ... CF16: =(SUM(CF8,CF12)/CF6)*-(MAX('Property Cash Flow'!CF6-Assumptions!$B$22,0)) -> -110156.18
