Workbook
Name ReservesGrowth: Assumptions!$B$25
Name PrefMo: Assumptions!$B$70
Name DispCost: Assumptions!$B$17
Name ParkGrowth: Assumptions!$B$23
Name ResidLP: Assumptions!$B$74
Name CloseDate: Assumptions!$B$12
Name CatchupGP: Assumptions!$B$71
Name SpecBuildout: Assumptions!$B$64
Name AntennaGrowth: Assumptions!$B$24
Name BldgSF: Assumptions!$B$5
Name RenoBudget: Assumptions!$B$50
Name HoldMonths: Assumptions!$B$15
Name ExpGrowth: Assumptions!$B$21
Name LeaseTable: Assumptions!$A$56:$J$59
Name GPTarget: Assumptions!$B$72
Name MgmtFeePct: Assumptions!$B$41
Name SpecTI: Assumptions!$B$63
Name RentGrowth: Assumptions!$B$20
Name ResidGP: Assumptions!$B$73
Name ReservesPSF: Assumptions!$B$42
Name ReimbPool: Assumptions!$B$40
Name RenoDuration: Assumptions!$B$51
Name GPShare: Assumptions!$B$67
Name RenewDiscount: Assumptions!$B$62
Name LPShare: Assumptions!$B$68
Name PurchasePrice: Assumptions!$B$6
Name ExitCap: Assumptions!$B$16

Sheet Assumptions
A1: SouthPark Centre
A2: 4800 Sharon Road, Charlotte, NC 2821 | B2: Class B+ Multi-Tenant Office | D2: All inputs blue, formulas black
A4: PROPERTY
A5: Building SF (RSF)
A6: Purchase Price
A7: Acquisition Costs (% of gross)
A8: Price per SF
A9: Stories
A10: Floor Plate (SF)
A11: Parking Spaces
A12: Close Date
A14: HOLD & EXIT
A15: Hold Period (months)
A16: Exit Cap Rate
... A25: Building Reserves Growth
A27: OPERATING EXPENSES (Annual, Year 1) | C27: Reimbursable?
A28: Real Estate Taxes
A29: Insurance
A30: Utilities
A31: Repairs & Maintenance
A32: Janitorial
A33: Landscaping
A34: Security
A35: Elevator
A36: HVAC
A37: General & Admin
A38: Marketing
A39: Total OpEx (ex-mgmt fee)
... A42: Building Reserves ($/SF/yr)
A44: OTHER INCOME (Annual) | C44: Growth
A45: Parking Income
A46: Antenna Income (T-Mobile)
A47: Storage Income
A49: RENOVATION
A50: Renovation Budget (Pinnacle)
A51: Renovation Sensitivity
A54: LEASING ASSUMPTIONS BY SIZE (Standard Guide) | L54: <-- Sensi input
A55: Min SF | B55: Bucket Label | C55: Mkt Rent $/SF | D55: Renew % | E55: Downtime (mo) | F55: New TI $/SF | G55: Ren TI $/SF | H55: LC % | I55: Free New (mo) | J55: Free Ren (mo) | K55: Downtime (mo) - base reference
K56: 7
K57: 6
...

Sheet Rent Roll
B1: SouthPark Centre — Rent Roll
O3: Cols N–U: occupied = expiry mo# + size lookups; vacant = lease-up commencement mo# (blue) + size lookups
A4: Size Rank | B4: # | C4: Tenant | D4: Suite | E4: Flr | F4: SF | G4: Rent $/SF | H4: Annual Rent | I4: Esc % | J4: Esc Mo | K4: Start | L4: Expiry | M4: Renewal | N4: Status | O4: Expiry Mo# | P4: Size Key | Q4: Bucket | R4: Mkt Rent $/SF | S4: Downtime | T4: New TI $/SF | U4: LC % | V4: Free New | W4: Renew % | X4: Blend Rent $/SF | Y4: 1st Esc Date >close
A5: =RANK(F5,$F$5:$F$32) -> #N/A | B5: 1 | C5: Meridian Financial Group
A6: =RANK(F6,$F$5:$F$32) -> #N/A | B6: 2 | C6: Southeast Regional Health
A7: =RANK(F7,$F$5:$F$32) -> #N/A | B7: 3 | C7: Carter & Associates Law
A8: =RANK(F8,$F$5:$F$32) -> #N/A | B8: 4 | C8: Pinnacle Wealth Advisors
A9: =RANK(F9,$F$5:$F$32) -> #N/A | B9: 5 | C9: TechBridge Solutions
A10: =RANK(F10,$F$5:$F$32) -> #N/A | B10: 6 | C10: Brightpath Insurance
A11: =RANK(F11,$F$5:$F$32) -> #N/A | B11: 7 | C11: Caldwell Consulting Group
A12: =RANK(F12,$F$5:$F$32) -> #N/A | B12: 8 | C12: Queen City Accounting
A13: =RANK(F13,$F$5:$F$32) -> #N/A | B13: 9 | C13: Monarch Marketing Group
A14: =RANK(F14,$F$5:$F$32) -> #N/A | B14: 10 | C14: Davidson & Reed Architects
A15: =RANK(F15,$F$5:$F$32) -> #N/A | B15: 11 | C15: Greenway Environmental
A16: =RANK(F16,$F$5:$F$32) -> #N/A | B16: 12 | C16: Trellis HR Solutions
... A32: =RANK(F32,$F$5:$F$32) -> #N/A | B32: 28 | C32: Vacant — Suite 830
B34: TOTAL | C34: 28 entries | F34: =SUM(F5:F32) -> 0 | G34: =H34/F34 -> #DIV/0! | H34: =SUM(H5:H32) -> 0 | L34: {=SUMPRODUCT((L5:L32)*(H5:H32)*(N5:N32<>"Vacant"))/H34} -> #DIV/0! | X34: =SUMPRODUCT(X5:X32,F5:F32)/F34 -> #DIV/0!
B36: SF check vs Building SF: | F36: =F34-BldgSF -> 0 | G36: =IF(F36=0,"OK","CHECK") -> OK
B38: SPEC SUITES (Meridian re-demise — 76,000 SF, not additive)
B40: # | C40: Suite | D40: Floor | F40: SF | O40: Commence Mo# | T40: TI $/SF | U40: LC % | V40: Free New | X40: Rent $/SF
B41: 29 | C41: Suite 610 | D41: 6 | P41: Adjusted per VP feedback (email 9) | T41: =SpecTI
B42: 30 | C42: Suite 620 | D42: 6 | P42: Adjusted per VP feedback (email 9) | T42: =SpecTI
B43: 31 | C43: Suite 710 | D43: 7 | P43: Adjusted per VP feedback (email 9) | T43: =SpecTI
B44: 32 | C44: Suite 720 | D44: 7 | P44: Adjusted per VP feedback (email 9) | T44: =SpecTI
B45: 33 | C45: Suite 810 | D45: 8 | P45: Adjusted per VP feedback (email 9) | T45: =SpecTI
B46: 34 | C46: Suite 820 | D46: 8 | P46: Adjusted per VP feedback (email 9) | T46: =SpecTI
C47: Total (= Meridian 76,000) | F47: =SUM(F41:F46) -> 0

Sheet Rent Roll Calc
A1: SouthPark Centre — Rent Roll Calc
A3: Month # | D3: 0 | E3: =D3+1 -> 1 | F3: =E3+1 -> 2 | G3: =F3+1 -> 3 | H3: =G3+1 -> 4 | I3: =H3+1 -> 5 | J3: =I3+1 -> 6 | K3: =J3+1 -> 7 | L3: =K3+1 -> 8 | ... BX3: =BW3+1 -> 72
A4: Period End | D4: =EOMONTH(CloseDate,D3) -> 1 | E4: =EOMONTH(CloseDate,E3) -> 32 | F4: =EOMONTH(CloseDate,F3) -> 60 | G4: =EOMONTH(CloseDate,G3) -> 91 | H4: =EOMONTH(CloseDate,H3) -> 121 | I4: =EOMONTH(CloseDate,I3) -> 152 | J4: =EOMONTH(CloseDate,J3) -> 182 | K4: =EOMONTH(CloseDate,K3) -> 213 | ... BX4: =EOMONTH(CloseDate,BX3) -> 2192
A5: Year | D5: =INT((D3-1)/12)+1 -> 0 | E5: =INT((E3-1)/12)+1 -> 1 | F5: =INT((F3-1)/12)+1 -> 1 | G5: =INT((G3-1)/12)+1 -> 1 | H5: =INT((H3-1)/12)+1 -> 1 | I5: =INT((I3-1)/12)+1 -> 1 | J5: =INT((J3-1)/12)+1 -> 1 | K5: =INT((K3-1)/12)+1 -> 1 | ... BX5: =INT((BX3-1)/12)+1 -> 6
A6: Rent Growth Index
A7: Expense Growth Index
A9: ='Rent Roll'!C5 -> Meridian Financial Group | B9: {=INDEX('Rent Roll'!$F$5:$F$46,MATCH('Rent Roll Calc'!A9,'Rent Roll'!$C$5:$C$46,0))}
B10: Occupancy Flag
B11: In-Place Rent
B12: Re-Let Flag
B13: Re-Let Rent (gross)
B14: Free Rent Adj
B15: Net Base Rent
B16: Opex Recovery (NNN)
B17: TI (capital)
B18: LC (capital)
A19: ='Rent Roll'!C6 -> Southeast Regional Health | B19: {=INDEX('Rent Roll'!$F$5:$F$46,MATCH('Rent Roll Calc'!A19,'Rent Roll'!$C$5:$C$46,0))}
B20: Occupancy Flag
B21: In-Place Rent
B22: Re-Let Flag
B23: Re-Let Rent (gross)
B24: Free Rent Adj
B25: Net Base Rent
B26: Opex Recovery (NNN)
B27: TI (capital)
B28: LC (capital)
A29: ='Rent Roll'!C7 -> Carter & Associates Law | B29: {=INDEX('Rent Roll'!$F$5:$F$46,MATCH('Rent Roll Calc'!A29,'Rent Roll'!$C$5:$C$46,0))}
B30: Occupancy Flag
B31: In-Place Rent
B32: Re-Let Flag
B33: Re-Let Rent (gross)
B34: Free Rent Adj
B35: Net Base Rent
B36: Opex Recovery (NNN)
B37: TI (capital)
B38: LC (capital)
A39: ='Rent Roll'!C8 -> Pinnacle Wealth Advisors | B39: {=INDEX('Rent Roll'!$F$5:$F$46,MATCH('Rent Roll Calc'!A39,'Rent Roll'!$C$5:$C$46,0))}
B40: Occupancy Flag
B41: In-Place Rent
B42: Re-Let Flag
...

Sheet IC Summary
A1: INVESTMENT COMMITTEE SUMMARY
A3: DEAL OVERVIEW
A4: Property Name | D4: =Assumptions!A1 -> SouthPark Centre
A5: Address | D5: =Assumptions!A2 -> 4800 Sharon Road, Charlotte, NC 2821
A6: Submarket | D6: ='Rental Comp Analysis'!C3
A7: Total SF | D7: =BldgSF
A8: Stories | E8: from OM
A9: Year Built | E9: from OM
A10: Purchase Price
A11: Price / SF
A12: Going-In Cap Rate (Reconciled)
A13: Physical Occupancy (Corrected)
A14: Number of Tenants (Actual)
A15: WALT (Years)
A16: Largest Tenant
A17: Near-Term Rollover Exposure (SF)
A19: MARKET CONTEXT
A20: Submarket Vacancy
A21: Class B+ Asking Rent (NNN)
A22: 12-Month Rent Growth
... A26: TENANCY SUMMARY
A27: WALT | D27: =D15
A28: Top 5 Tenant Concentration (% of SF)
A29: Near-Term Rollover (SF / % of Bldg) | D29: =D17
A30: Avg Mark-to-Market Spread
A31: Weighted Avg In-Place Rent
A33: FINANCIAL SUMMARY
A34: Broker's Stated NOI
A35: Reconciled NOI
A36: Year 1 Proforma NOI
A37: Stabilized NOI
A38: Exit Year NOI
A39: Unlevered IRR
A41: DEBT TERMS
A42: Selected Lender
A43: Loan Type
... A60: JV STRUCTURE & RETURNS
A61: GP / LP Equity Split | D61: =Assumptions!C67
A62: Preferred Return | D62: =Assumptions!B69
A63: Promote Structure
...

Sheet LOI
A1: LETTER OF INTENT
A3: HARBORVIEW CAPITAL PARTNERS
A5: PROPERTY DETAILS
A6: Property Name:
A7: Address:
A8: Total SF: | B8: =BldgSF
A10: TRANSACTION TERMS
A11: Buyer:
A12: Purchase Price:
A13: Deposit:
A14: Due Diligence Period:
A15: Financing Contingency:
A16: Target Close Date: | B16: =CloseDate
A18: CONDITIONS
A19: Access:
A20: Exclusivity:
A21: Existing Contracts:
A22: Tenant Estoppels:
A23: Title & Survey:
A24: Environmental:
A26: EXPIRATION
A27: This LOI expires:

Sheet Property Cash Flow
A1: SouthPark Centre — Cash Flow Summary
A2: in $'000s
A3: Year # | D3: 0 | E3: =D3+1 -> 1 | F3: =E3+1 -> 2 | G3: =F3+1 -> 3 | H3: =G3+1 -> 4 | I3: =H3+1 -> 5 | J3: =I3+1 -> 6 | L3: =INT((L4-1)/12)+1 -> 0 | M3: =INT((M4-1)/12)+1 -> 1 | N3: =INT((N4-1)/12)+1 -> 1 | O3: =INT((O4-1)/12)+1 -> 1 | P3: =INT((P4-1)/12)+1 -> 1 | Q3: =INT((Q4-1)/12)+1 -> 1 | R3: =INT((R4-1)/12)+1 -> 1 | S3: =INT((S4-1)/12)+1 -> 1 | ... CF3: =INT((CF4-1)/12)+1 -> 6
A4: Month # | D4: 0 | E4: =D4+12 -> 12 | F4: =E4+12 -> 24 | G4: =F4+12 -> 36 | H4: =G4+12 -> 48 | I4: =H4+12 -> 60 | J4: =I4+12 -> 72 | L4: ='Rent Roll Calc'!D3 -> 0 | M4: ='Rent Roll Calc'!E3 -> 1 | N4: ='Rent Roll Calc'!F3 -> 2 | O4: ='Rent Roll Calc'!G3 -> 3 | P4: ='Rent Roll Calc'!H3 -> 4 | Q4: ='Rent Roll Calc'!I3 -> 5 | R4: ='Rent Roll Calc'!J3 -> 6 | S4: ='Rent Roll Calc'!K3 -> 7 | ... CF4: ='Rent Roll Calc'!BX3 -> 72
A5: Period End | D5: =+EOMONTH(CloseDate,0) -> 1 | E5: =EOMONTH(D5,12) -> 366 | F5: =EOMONTH(E5,12) -> 731 | G5: =EOMONTH(F5,12) -> 1096 | H5: =EOMONTH(G5,12) -> 1461 | I5: =EOMONTH(H5,12) -> 1827 | J5: =EOMONTH(I5,12) -> 2192 | L5: ='Rent Roll Calc'!D4 -> 1 | M5: ='Rent Roll Calc'!E4 -> 32 | N5: ='Rent Roll Calc'!F4 -> 60 | O5: ='Rent Roll Calc'!G4 -> 91 | P5: ='Rent Roll Calc'!H4 -> 121 | Q5: ='Rent Roll Calc'!I4 -> 152 | R5: ='Rent Roll Calc'!J4 -> 182 | S5: ='Rent Roll Calc'!K4 -> 213 | ... CF5: ='Rent Roll Calc'!BX4 -> 2192
A6: Occupancy %
A8: Gross Rental Income
A9: Free Rent
A10: Net Rental Income
A12: Expense Recovery (NNN)
A13: Other Income
A14: Effective Gross Income
A16: General Vacancy Adjustment
A17: Operating Expenses
A18: Management Fee
A19: Net Operating Income
A21: Renovation CapEx
... A34: Total Unlevered Cash Flow
A35: IRR | B35: =XIRR(L34:CF34,$L$5:$CF$5) -> #NUM!
A36: Required Capital
A37: Profit
A38: MoIC | B38: =B37/B36+1 -> #DIV/0!
A41: Financing Cash Flow
A42: Acquisition / Dev Loan
A43: BoP Balance
A44: Drawdown | B44: ='Leverage Options'!B10
A45: PIK Interest | B45: ='Leverage Options'!B9
A46: Scheduled Amortization | B46: n/a
A47: Repayment | B47: ='Leverage Options'!B13
A48: EoP Balance
A50: Cash Interest | B50: n/a
A51: Loan Closing Costs | B51: ='Leverage Options'!B14
A52: Origination Fee | B52: ='Leverage Options'!$B$20
A54: Acquisition / Dev Loan Cash Flow
A58: Permanent Loan
A59: BoP Balance
A60: Drawdown | B60: =MIN('Leverage Options'!B27,'Leverage Options'!B28) -> 0
A61: Scheduled Amortization | B61: ='Leverage Options'!B16
A62: Repayment
A63: EoP Balance
...

Sheet CapEx Schedule
A1: RENOVATION TIMELINE - SOUTHPARK CENTRE
A2: Prepared by: Pinnacle Builders Inc.
A3: Date: May 28, 2026 | Revision: 0 | Contract Value: $7,500,000
A4: Assumes close August 1, 2026. Months numbered from close.
A6: Work Item | B6: Budget | C6: Start Month | D6: Duration | E6: 1 | F6: 2 | G6: 3 | H6: 4 | I6: 5 | J6: 6 | K6: 7 | L6: 8 | M6: 9 | N6: 10 | O6: 11 | P6: 12 | Q6: 13 | R6: 14 | S6: 15 | T6: 16 | U6: 17 | V6: 18
A7: COMMON AREA RENOVATION
A8: General Conditions & Mobilization
A9: Lobby Demolition
A10: Lobby Renovation (Entrance + Reception)
A11: Corridor Refresh - Floor 1
A12: Corridor Refresh - Floor 2
A13: Corridor Refresh - Floor 3
A14: Corridor Refresh - Floor 4
A15: Corridor Refresh - Floor 5
A16: Restroom Renovation - Floor 1
A17: Restroom Renovation - Floor 2
A18: Restroom Renovation - Floor 3
... A36: Contingency (~7% of hard costs)
A38: CapEx Sensitivity | B38: =RenoDuration | E38: =SUM(E8:E23,E26:E32,E35:E36)*$B38 -> 0 | F38: =SUM(F8:F23,F26:F32,F35:F36)*$B38 -> 0 | G38: =SUM(G8:G23,G26:G32,G35:G36)*$B38 -> 0 | H38: =SUM(H8:H23,H26:H32,H35:H36)*$B38 -> 0 | I38: =SUM(I8:I23,I26:I32,I35:I36)*$B38 -> 0 | J38: =SUM(J8:J23,J26:J32,J35:J36)*$B38 -> 0 | K38: =SUM(K8:K23,K26:K32,K35:K36)*$B38 -> 0 | L38: =SUM(L8:L23,L26:L32,L35:L36)*$B38 -> 0 | ... V38: =SUM(V8:V23,V26:V32,V35:V36)*$B38 -> 0
A39: Total CapEx | B39: =SUM(E39:V39) -> 0 | E39: =SUM(E8:E23,E26:E38) -> 0 | F39: =SUM(F8:F23,F26:F38) -> 0 | G39: =SUM(G8:G23,G26:G38) -> 0 | H39: =SUM(H8:H23,H26:H38) -> 0 | I39: =SUM(I8:I23,I26:I38) -> 0 | J39: =SUM(J8:J23,J26:J38) -> 0 | K39: =SUM(K8:K23,K26:K38) -> 0 | L39: =SUM(L8:L23,L26:L38) -> 0 | ... V39: =SUM(V8:V23,V26:V38) -> 0
A42: NOTES
A43: 1. Spec suite buildout at $65/SF per James Whitfield's site assessment (Email 5, May 31).
A44: 2. Floor 6 spec suites assume access beginning Month 4 (Meridian lease expires Oct 31, 2026).
A45: 3. Floors 7 and 8 phased at 2-month intervals to manage subcontractor scheduling.
A46: 4. Common area renovation and spec suites run in parallel where possible.
A47: 5. TI allowance for spec suites not included herein
A48: 6. Budget excludes ongoing tenant TI/LC for existing tenant rollovers (separate line in operating budget).
A49: 7. Contingency of 5% included in line items. No separate contingency line.

Sheet Waterfall
A1: SouthPark Centre — JV Equity Waterfall
A2: GP 10% / LP 90% · 8% pref (effective annual, monthly compounding) · 50/50 catch-up to 20% GP profit share · 80/20 LP/GP residual
A3: Year # | D3: ='Property Cash Flow'!L3 -> 0 | E3: ='Property Cash Flow'!M3 -> 1 | F3: ='Property Cash Flow'!N3 -> 1 | G3: ='Property Cash Flow'!O3 -> 1 | H3: ='Property Cash Flow'!P3 -> 1 | I3: ='Property Cash Flow'!Q3 -> 1 | J3: ='Property Cash Flow'!R3 -> 1 | K3: ='Property Cash Flow'!S3 -> 1 | ... BL3: ='Property Cash Flow'!BT3 -> 5
A4: Month # | D4: ='Property Cash Flow'!L4 -> 0 | E4: ='Property Cash Flow'!M4 -> 1 | F4: ='Property Cash Flow'!N4 -> 2 | G4: ='Property Cash Flow'!O4 -> 3 | H4: ='Property Cash Flow'!P4 -> 4 | I4: ='Property Cash Flow'!Q4 -> 5 | J4: ='Property Cash Flow'!R4 -> 6 | K4: ='Property Cash Flow'!S4 -> 7 | ... BL4: ='Property Cash Flow'!BT4 -> 60
A5: Period End | D5: ='Property Cash Flow'!L5 -> 1 | E5: ='Property Cash Flow'!M5 -> 32 | F5: ='Property Cash Flow'!N5 -> 60 | G5: ='Property Cash Flow'!O5 -> 91 | H5: ='Property Cash Flow'!P5 -> 121 | I5: ='Property Cash Flow'!Q5 -> 152 | J5: ='Property Cash Flow'!R5 -> 182 | K5: ='Property Cash Flow'!S5 -> 213 | ... BL5: ='Property Cash Flow'!BT5 -> 1827
A7: DEAL CASH FLOW
A8: Levered Cash Flow (Property CF)
A9: Capital Call — Total Equity
A10: Available for Distribution
A12: CAPITAL CONTRIBUTIONS
A13: LP Contribution
A14: GP Contribution
A15: Cumulative Called — Total
A16: Cumulative Called — LP
A17: Cumulative Called — GP
A19: LP LEDGER
A20: BoP Unreturned Capital
... A91: LP IRR < Deal IRR < GP IRR (promote intact)

Sheet Leverage Options
A1: Lender Quote Comparison — SouthPark Centre
B2: 2 | D2: 1 | E2: 2 | F2: 3
B3: Active Selection | D3: STALE QUOTE
A4: Term
A5: Loan Type
A6: Rate Type
A7: Spread
A8: Current SOFR
A9: All-In Rate (indicative)
A10: Maximum LTC
A11: Maximum LTV (stabilized)
A12: Min DSCR at Conversion (NOI based)
A13: Conversion Month
A14: Closing Costs
A15: Interest-Only Period
... A32: Lender Scenario Analysis (sensitivity)
B33: Active | D33: =D4 | E33: =E4 | F33: =F4 | H33: Max
D34: =D2 -> 1 | E34: =E2 -> 2 | F34: =F2 -> 3
A35: Levered IRR
A36: Levered MoIC

Sheet Exit Analysis
A1: SouthPark Centre — Exit Analysis
A3: EXIT VALUATION
A4: Exit Month
A5: Forward 12-Month NOI
A6: Exit Cap Rate
A7: Gross Exit Value
A8: Exit Value $/SF
A9: Less: Disposition Costs
A10: Net Sale Proceeds
A12: UNLEVERED RETURN SUMMARY
A13: Purchase Price (net)
A14: Additional Capital Required
... A24: Exit value > purchase price

Sheet Sales Comp Analysis
A1: # | B1: Address | C1: Submarket | D1: Class | E1: SF | F1: Sale Date | G1: Price ($) | H1: $/SF | I1: Cap Rate | J1: Occ at Sale | K1: Buyer Type | L1: Notes | M1: Comp Type (see legend)
A2: 1
A3: 2
A4: 3
A5: 4
A6: 5
A7: 6
A8: 7
A9: 8
A10: 9
A11: 10
A12: 11
A13: 12
... A26: 25
A27: Average of Current Market Comps
A28: Average of Crisis Era Comps
A29: Target Property (Going-in)
A30: Target Property (Underwritten)
B33: Legend:
B34: (1) White = current market comps (primary benchmarks)
B35: (2) Yellow = crisis-era trades (stress-test / floor) | D35: #FFF2CC
B36: (3) Gray = incomplete data (exclude from statistics) | D36: #F2F2F2
B37: (4) Pink = non-comparable (wrong submarket/type/size) | D37: #FCE4EC

Sheet Rental Comp Analysis
A1: # | B1: Address | C1: Submarket | D1: Tenant | E1: SF | F1: Lease Date | G1: Term (yr) | H1: Rent $/SF (NNN) | I1: Escalation | J1: TI $/SF | K1: Free Rent (mo) | L1: Notes | M1: Comp Type (see legend)
A2: 1
A3: 2
A4: 3
A5: 4
A6: 5
A7: 6
A8: 7
A9: 8
A10: 9
A11: 10
A12: 11
A13: 12
... A51: 50
A52: Average of Current Market Comps
A53: Target Property Underwriting (Vacancy)
B55: (1) Yellow highlight = Meridian BTS (only large-block transaction) | D55: #FFF2CC
B56: (2) White = current comps, SouthPark area (usable benchmarks)
B57: (3) Gray = older transactions (2023 or earlier) | D57: #F2F2F2
B58: (4) Purple = wrong submarket | D58: #E8EAF6
B59: (5) Pink = wrong property type/class | D59: #FCE4EC
B60: (6) Light yellow = incomplete data | D60: #FFF9C4

Sheet Pure Reference--->

Sheet T-12 Operating Statement
A1: Line Item | B1: Jun 2025 | C1: Jul 2025 | D1: Aug 2025 | E1: Sep 2025 | F1: Oct 2025 | G1: Nov 2025 | H1: Dec 2025 | I1: Jan 2026 | J1: Feb 2026 | K1: Mar 2026 | L1: Apr 2026 | M1: May 2026 | N1: TOTAL
A2: REVENUE
A3: Base Rental Revenue
A4: Expense Reimbursements
A5: Parking Income
A6: Antenna / Telecom Income
A7: Storage Income
A8: Other Income - Lease Termination Fee
A10: TOTAL REVENUE
A12: OPERATING EXPENSES
A13: Real Estate Taxes
A14: Insurance
A15: Utilities
... A28: NET OPERATING INCOME

Sheet Vendor Contracts
A1: Vendor | B1: Service | C1: Annual Cost | D1: Start Date | E1: Expiry | F1: Auto-Renew | G1: Status | H1: Notes

Sheet SouthPark Submarket
A1: Charlotte Office Market
A2: SouthPark Submarket Report - Q1 2026
A3: Prepared by Charlotte Commercial Research
A5: SUBMARKET OVERVIEW
A6: Total Inventory
A7: Number of Buildings
A8: Average Building Age
A10: VACANCY & OCCUPANCY
A11: Overall Vacancy Rate
A12: Class A Vacancy
A13: Class B/B+ Vacancy
A14: Class C Vacancy
... A48: Overall Trend
